Workbook
Name AboveSeal_Depth: '[3]Geo-Activity Interaction'!$E$35
Name AboveSeal_Depth_Units: '[3]Geo-Activity Interaction'!$F$35
Name AGRType: [4]InputsAndConstants!$G$8
Name AuxLoadTot: [5]Performance!$F$19
Name BioFeedAR: [4]EQDesignParameters!$C$7
Name booster_count: '[6]User Interface'!$G$10
Name Capture: [4]InputsAndConstants!$G$12
Name CarbonReplacement: [4]EQDesignParameters!$C$237
Name CarbonVolume: [4]EQDesignParameters!$C$238
Name Case_Number: '[4]Model Interface'!$A$17
Name co2_density: '[6]User Interface'!$G$9
Name co2_flow_rate: '[6]User Interface'!$C$7
Name CO2Emissions: [4]Emissions!$F$11
Name CO2TSpertonne: #REF!
Name CoalFeedAR: [4]EQDesignParameters!$C$6
Name CoalPrice: '[7]COE Calc'!$O$6
Name CondDuty: [4]EQDesignParameters!$C$106
Name COSBedLife: [4]EQDesignParameters!$C$169
Name COSInitialFill: [4]EQDesignParameters!$C$168
Name CWFlow: [5]EQDesignParameters!$C$53
Name CWFlowVol: [5]EQDesignParameters!$C$54
Name CWRange: [5]EQDesignParameters!$C$51
Name d360.: '[3]Geol Sal'!$D$98
Name Dedicated: '[8]state coordinates'!#REF!
Name Drow: [9]InputsAndConstants!$C$12
Name Engineer_Rate: [3]Activity_Inputs!$E$10
Name Engineer_Rate_Units: [3]Activity_Inputs!$F$10
Name Field_Rate: [3]Activity_Inputs!$E$12
Name Field_Rate_Units: [3]Activity_Inputs!$F$12
Name Frow: [9]InputsAndConstants!$C$7
Name Geologist_Rate: [3]Activity_Inputs!$E$9
Name Geologist_Rate_Units: [3]Activity_Inputs!$F$9
Name graphic: INDIRECT('[8]Input Output Interface'!$C$10)
Name GrossPower: [5]Performance!$F$7
Name Groundwater_Depth: '[3]Geo-Activity Interaction'!$E$36
Name Groundwater_Depth_Units: '[3]Geo-Activity Interaction'!$F$36
Name HClNaOHFlow: [4]EQDesignParameters!$C$374
Name HgEmissions: [4]InputsAndConstants!$C$63
Name hp2kW: [4]InputsAndConstants!$G$56
Name HRSGDuty: [5]EQDesignParameters!$C$25
Name infrastructure: '[8]Input Output Interface'!$C$10
Name Injection_Depth: '[3]Geo-Activity Interaction'!$E$32
Name Injection_Depth_Units: '[3]Geo-Activity Interaction'!$F$32
Name InReservoir_Depth: '[3]Geo-Activity Interaction'!$E$34
Name InReservoir_Depth_Units: '[3]Geo-Activity Interaction'!$F$34
Name IQ_CH: 110000
Name IQ_CQ: 5000
Name IQ_CY: 10000
Name IQ_DAILY: 500000
Name IQ_FH: 100000
Name IQ_FQ: 500
Name IQ_FY: 1000
Name IQ_LTM: 2000
Name IQ_MONTH: 15000
Name IQ_NTM: 6000
Name IQ_WEEK: 50000
Name IQ_YTD: 3000
Name L_PL: '[10]Eng Mod'!$D$16
Name Landman_Rate: [3]Activity_Inputs!$E$11
Name Landman_Rate_Units: [3]Activity_Inputs!$F$11

Sheet LCA
A1: AR6, 100-year GWP | B1: Sum of land prep through harvesting GWP (kg CO2e/kg wet biomass) | C1: Transportation GWP (kg CO2e/kg-km) | D1: Gasification GWP (kg CO2e/kg H2) | E1: CO2 T&S GWP (kg CO2e/kg CO2) transport distance is for 100 mi | F1: Moisture content of biomass (kg water/kg biomass) | G1: MC using | H1: Sum of land prep through harvesting GWP (kg CO2e/dry ton biomass) | L1: Average MC | M1: Average LCA | N1: Dry tons per plant | O1: Land Prep to Roadside | P1: Transportation LCA (roadside-plant gate) (CO2e) | Q1: Gasification (CO2e) | R1: T&S | S1: total LCA? | T1: Land Prep to Roadside | U1: Transportation LCA (roadside-plant gate) (CO2e) | V1: Gasification (CO2e) | W1: T&S
A2: Willow | B2: -1.26 | C2: 0.00011776248 | D2: 20.2 | E2: 0.01094 | F2: 0.5 | G2: 0.6 | H2: =B2*(1-G2)*970.2 -> -488.9808 | L2: =IF('[1]All Data '!BE7="","",'[1]All Data '!BE7) -> 0.055 | M2: =IF('[1]All Data '!BF7="","",'[1]All Data '!BF7) -> 4767.5628 | N2: =IF('[1]All Data '!BB7="","",'[1]All Data '!BC7/'[1]All Data '!BH7) -> 269774.46 | O2: =IF(N2="","",M2*N2) -> 1.2861667e+09 | P2: =IF(M2="","",$C$2*(1-L2)*907.2/0.621371*N2*[1]Transportation!$M$40) -> 4207875.3 | Q2: =IF(L2="","",IF([1]Inputs_Outputs!$B$5="Herbaceous",(LCA!$E$29*'[1]LOCH Calc COE Calc'!$C$28),IF([1]Inputs_Outputs!$B$5="Woody",$E$28*'[1]LOCH Calc COE Calc'!$C$28,IF([1]Inputs_Outputs!$B$5="Paper",(LCA!$E$30*'[1]LOCH Calc COE Calc'!$C$28),IF([1]Inputs_Outputs!$B$5="Forest",LCA!$E$31*'[1]LOCH Calc COE Calc'!$C$28))))) -> 74440334 | R2: =IF(M2="","",$E$2*1000*'[1]LOCH Calc COE Calc'!$C$44) -> 4896457.3 | S2: =IF(N2="","",SUM(O2:R2)/('[1]LOCH Calc COE Calc'!$C$28)) -> 59.064397 | T2: =IF(L2="","",O2/'[1]LOCH Calc COE Calc'!$C$28) -> 55.461802 | U2: =IF(L2="","",P2/'[1]LOCH Calc COE Calc'!$C$28) -> 0.18145109 | V2: =IF(L2="","",Q2/'[1]LOCH Calc COE Calc'!$C$28) -> 3.21 | W2: =IF(L2="","",R2/'[1]LOCH Calc COE Calc'!$C$28) -> 0.21114397
A3: Pine | B3: -1.32 | C3: 0.00011776248 | D3: 20.21 | E3: 0.01094 | F3: 0.5 | G3: 0.57 | H3: =B3*(1-G3)*970.2 -> -550.68552 | L3: =IF('[1]All Data '!BE8="","",'[1]All Data '!BE8) -> 0.055 | M3: =IF('[1]All Data '!BF8="","",'[1]All Data '!BF8) -> 4767.5628 | N3: =IF('[1]All Data '!BB8="","",'[1]All Data '!BC8/'[1]All Data '!BH8) -> 281924.17 | O3: =IF(N3="","",M3*N3) -> 1.3440912e+09 | P3: =IF(M3="","",$C$2*(1-L3)*907.2/0.621371*N3*[1]Transportation!$M$40) -> 4397383.4 | Q3: =IF(L3="","",IF([1]Inputs_Outputs!$B$5="Herbaceous",(LCA!$E$29*'[1]LOCH Calc COE Calc'!$C$28),IF([1]Inputs_Outputs!$B$5="Woody",$E$28*'[1]LOCH Calc COE Calc'!$C$28,IF([1]Inputs_Outputs!$B$5="Paper",(LCA!$E$30*'[1]LOCH Calc COE Calc'!$C$28),IF([1]Inputs_Outputs!$B$5="Forest",LCA!$E$31*'[1]LOCH Calc COE Calc'!$C$28))))) -> 74440334 | R3: =IF(M3="","",$E$2*1000*'[1]LOCH Calc COE Calc'!$C$44) -> 4896457.3 | S3: =IF(N3="","",SUM(O3:R3)/('[1]LOCH Calc COE Calc'!$C$28)) -> 61.570376 | T3: =IF(L3="","",O3/'[1]LOCH Calc COE Calc'!$C$28) -> 57.959609 | U3: =IF(L3="","",P3/'[1]LOCH Calc COE Calc'!$C$28) -> 0.18962302 | V3: =IF(L3="","",Q3/'[1]LOCH Calc COE Calc'!$C$28) -> 3.21 | W3: =IF(L3="","",R3/'[1]LOCH Calc COE Calc'!$C$28) -> 0.21114397
A4: Poplar | B4: -1.33 | C4: 0.00011776248 | D4: 20.22 | E4: 0.01094 | F4: 0.5 | G4: 0.45 | H4: =B4*(1-G4)*970.2 -> -709.7013 | L4: =IF('[1]All Data '!BE9="","",'[1]All Data '!BE9) -> 0.055 | M4: =IF('[1]All Data '!BF9="","",'[1]All Data '!BF9) -> 4767.5628 | N4: =IF('[1]All Data '!BB9="","",'[1]All Data '!BC9/'[1]All Data '!BH9) -> 279334.75 | O4: =IF(N4="","",M4*N4) -> 1.331746e+09 | P4: =IF(M4="","",$C$2*(1-L4)*907.2/0.621371*N4*[1]Transportation!$M$40) -> 4356994.3 | Q4: =IF(L4="","",IF([1]Inputs_Outputs!$B$5="Herbaceous",(LCA!$E$29*'[1]LOCH Calc COE Calc'!$C$28),IF([1]Inputs_Outputs!$B$5="Woody",$E$28*'[1]LOCH Calc COE Calc'!$C$28,IF([1]Inputs_Outputs!$B$5="Paper",(LCA!$E$30*'[1]LOCH Calc COE Calc'!$C$28),IF([1]Inputs_Outputs!$B$5="Forest",LCA!$E$31*'[1]LOCH Calc COE Calc'!$C$28))))) -> 74440334 | R4: =IF(M4="","",$E$2*1000*'[1]LOCH Calc COE Calc'!$C$44) -> 4896457.3 | S4: =IF(N4="","",SUM(O4:R4)/('[1]LOCH Calc COE Calc'!$C$28)) -> 61.036287 | T4: =IF(L4="","",O4/'[1]LOCH Calc COE Calc'!$C$28) -> 57.427261 | U4: =IF(L4="","",P4/'[1]LOCH Calc COE Calc'!$C$28) -> 0.18788137 | V4: =IF(L4="","",Q4/'[1]LOCH Calc COE Calc'!$C$28) -> 3.21 | W4: =IF(L4="","",R4/'[1]LOCH Calc COE Calc'!$C$28) -> 0.21114397
A5: Pruning residues, citrus | B5: -1.33 | C5: 0.00011776248 | D5: 20.22 | E5: 0.01094 | G5: 0.45 | H5: =B5*(1-G5)*970.2 -> -709.7013 | L5: =IF('[1]All Data '!BE10="","",'[1]All Data '!BE10) -> 0.055 | M5: =IF('[1]All Data '!BF10="","",'[1]All Data '!BF10) -> 4767.5628 | N5: =IF('[1]All Data '!BB10="","",'[1]All Data '!BC10/'[1]All Data '!BH10) -> 277684.33 | O5: =IF(N5="","",M5*N5) -> 1.3238775e+09 | P5: =IF(M5="","",$C$2*(1-L5)*907.2/0.621371*N5*[1]Transportation!$M$40) -> 4331251.5 | Q5: =IF(L5="","",IF([1]Inputs_Outputs!$B$5="Herbaceous",(LCA!$E$29*'[1]LOCH Calc COE Calc'!$C$28),IF([1]Inputs_Outputs!$B$5="Woody",$E$28*'[1]LOCH Calc COE Calc'!$C$28,IF([1]Inputs_Outputs!$B$5="Paper",(LCA!$E$30*'[1]LOCH Calc COE Calc'!$C$28),IF([1]Inputs_Outputs!$B$5="Forest",LCA!$E$31*'[1]LOCH Calc COE Calc'!$C$28))))) -> 74440334 | R5: =IF(M5="","",$E$2*1000*'[1]LOCH Calc COE Calc'!$C$44) -> 4896457.3 | S5: =IF(N5="","",SUM(O5:R5)/('[1]LOCH Calc COE Calc'!$C$28)) -> 60.695874 | T5: =IF(L5="","",O5/'[1]LOCH Calc COE Calc'!$C$28) -> 57.087959 | U5: =IF(L5="","",P5/'[1]LOCH Calc COE Calc'!$C$28) -> 0.18677129 | V5: =IF(L5="","",Q5/'[1]LOCH Calc COE Calc'!$C$28) -> 3.21 | W5: =IF(L5="","",R5/'[1]LOCH Calc COE Calc'!$C$28) -> 0.21114397
A6: Pruning residues, noncitrus | B6: -1.33 | C6: 0.00011776248 | D6: 20.22 | E6: 0.01094 | G6: 0.45 | H6: =B6*(1-G6)*970.2 -> -709.7013 | L6: =IF('[1]All Data '!BE11="","",'[1]All Data '!BE11) -> 0.055 | M6: =IF('[1]All Data '!BF11="","",'[1]All Data '!BF11) -> 4767.5628 | N6: =IF('[1]All Data '!BB11="","",'[1]All Data '!BC11/'[1]All Data '!BH11) -> 273463.45 | O6: =IF(N6="","",M6*N6) -> 1.3037542e+09 | P6: =IF(M6="","",$C$2*(1-L6)*907.2/0.621371*N6*[1]Transportation!$M$40) -> 4265415.3 | Q6: =IF(L6="","",IF([1]Inputs_Outputs!$B$5="Herbaceous",(LCA!$E$29*'[1]LOCH Calc COE Calc'!$C$28),IF([1]Inputs_Outputs!$B$5="Woody",$E$28*'[1]LOCH Calc COE Calc'!$C$28,IF([1]Inputs_Outputs!$B$5="Paper",(LCA!$E$30*'[1]LOCH Calc COE Calc'!$C$28),IF([1]Inputs_Outputs!$B$5="Forest",LCA!$E$31*'[1]LOCH Calc COE Calc'!$C$28))))) -> 74440334 | R6: =IF(M6="","",$E$2*1000*'[1]LOCH Calc COE Calc'!$C$44) -> 4896457.3 | S6: =IF(N6="","",SUM(O6:R6)/('[1]LOCH Calc COE Calc'!$C$28)) -> 59.825283 | T6: =IF(L6="","",O6/'[1]LOCH Calc COE Calc'!$C$28) -> 56.220206 | U6: =IF(L6="","",P6/'[1]LOCH Calc COE Calc'!$C$28) -> 0.18393232 | V6: =IF(L6="","",Q6/'[1]LOCH Calc COE Calc'!$C$28) -> 3.21 | W6: =IF(L6="","",R6/'[1]LOCH Calc COE Calc'!$C$28) -> 0.21114397
A7: Pruning residues, tree nuts | B7: -1.33 | C7: 0.00011776248 | D7: 20.22 | E7: 0.01094 | G7: 0.45 | H7: =B7*(1-G7)*970.2 -> -709.7013 | L7: =IF('[1]All Data '!BE12="","",'[1]All Data '!BE12) -> 0.055 | M7: =IF('[1]All Data '!BF12="","",'[1]All Data '!BF12) -> 4767.5628 | N7: =IF('[1]All Data '!BB12="","",'[1]All Data '!BC12/'[1]All Data '!BH12) -> 273411.9 | O7: =IF(N7="","",M7*N7) -> 1.3035084e+09 | P7: =IF(M7="","",$C$2*(1-L7)*907.2/0.621371*N7*[1]Transportation!$M$40) -> 4264611.2 | Q7: =IF(L7="","",IF([1]Inputs_Outputs!$B$5="Herbaceous",(LCA!$E$29*'[1]LOCH Calc COE Calc'!$C$28),IF([1]Inputs_Outputs!$B$5="Woody",$E$28*'[1]LOCH Calc COE Calc'!$C$28,IF([1]Inputs_Outputs!$B$5="Paper",(LCA!$E$30*'[1]LOCH Calc COE Calc'!$C$28),IF([1]Inputs_Outputs!$B$5="Forest",LCA!$E$31*'[1]LOCH Calc COE Calc'!$C$28))))) -> 74440334 | R7: =IF(M7="","",$E$2*1000*'[1]LOCH Calc COE Calc'!$C$44) -> 4896457.3 | S7: =IF(N7="","",SUM(O7:R7)/('[1]LOCH Calc COE Calc'!$C$28)) -> 59.814649 | T7: =IF(L7="","",O7/'[1]LOCH Calc COE Calc'!$C$28) -> 56.209607 | U7: =IF(L7="","",P7/'[1]LOCH Calc COE Calc'!$C$28) -> 0.18389764 | V7: =IF(L7="","",Q7/'[1]LOCH Calc COE Calc'!$C$28) -> 3.21 | W7: =IF(L7="","",R7/'[1]LOCH Calc COE Calc'!$C$28) -> 0.21114397
A8: Eucalyptus | B8: -1.04 | C8: 0.00011776248 | D8: 20.2 | E8: 0.01094 | F8: 0.543 | G8: 0.543 | H8: =B8*(1-G8)*970.2 -> -461.11666 | L8: =IF('[1]All Data '!BE13="","",'[1]All Data '!BE13) -> 0.055 | M8: =IF('[1]All Data '!BF13="","",'[1]All Data '!BF13) -> 4767.5628 | N8: =IF('[1]All Data '!BB13="","",'[1]All Data '!BC13/'[1]All Data '!BH13) -> 298009.78 | O8: =IF(N8="","",M8*N8) -> 1.4207803e+09 | P8: =IF(M8="","",$C$2*(1-L8)*907.2/0.621371*N8*[1]Transportation!$M$40) -> 4648282.8 | Q8: =IF(L8="","",IF([1]Inputs_Outputs!$B$5="Herbaceous",(LCA!$E$29*'[1]LOCH Calc COE Calc'!$C$28),IF([1]Inputs_Outputs!$B$5="Woody",$E$28*'[1]LOCH Calc COE Calc'!$C$28,IF([1]Inputs_Outputs!$B$5="Paper",(LCA!$E$30*'[1]LOCH Calc COE Calc'!$C$28),IF([1]Inputs_Outputs!$B$5="Forest",LCA!$E$31*'[1]LOCH Calc COE Calc'!$C$28))))) -> 74440334 | R8: =IF(M8="","",$E$2*1000*'[1]LOCH Calc COE Calc'!$C$44) -> 4896457.3 | S8: =IF(N8="","",SUM(O8:R8)/('[1]LOCH Calc COE Calc'!$C$28)) -> 64.888168 | T8: =IF(L8="","",O8/'[1]LOCH Calc COE Calc'!$C$28) -> 61.266582 | U8: =IF(L8="","",P8/'[1]LOCH Calc COE Calc'!$C$28) -> 0.20044225 | V8: =IF(L8="","",Q8/'[1]LOCH Calc COE Calc'!$C$28) -> 3.21 | W8: =IF(L8="","",R8/'[1]LOCH Calc COE Calc'!$C$28) -> 0.21114397
A9: Barley straw | B9: -2.03 | C9: 0.00011776248 | D9: 20.2 | E9: 0.01094 | G9: 0.3 | H9: =B9*(1-G9)*970.2 -> -1378.6542 | L9: =IF('[1]All Data '!BE14="","",'[1]All Data '!BE14) -> 0.055 | M9: =IF('[1]All Data '!BF14="","",'[1]All Data '!BF14) -> 4767.5628 | N9: =IF('[1]All Data '!BB14="","",'[1]All Data '!BC14/'[1]All Data '!BH14) -> 285370.56 | O9: =IF(N9="","",M9*N9) -> 1.360522e+09 | P9: =IF(M9="","",$C$2*(1-L9)*907.2/0.621371*N9*[1]Transportation!$M$40) -> 4451139.3 | Q9: =IF(L9="","",IF([1]Inputs_Outputs!$B$5="Herbaceous",(LCA!$E$29*'[1]LOCH Calc COE Calc'!$C$28),IF([1]Inputs_Outputs!$B$5="Woody",$E$28*'[1]LOCH Calc COE Calc'!$C$28,IF([1]Inputs_Outputs!$B$5="Paper",(LCA!$E$30*'[1]LOCH Calc COE Calc'!$C$28),IF([1]Inputs_Outputs!$B$5="Forest",LCA!$E$31*'[1]LOCH Calc COE Calc'!$C$28))))) -> 74440334 | R9: =IF(M9="","",$E$2*1000*'[1]LOCH Calc COE Calc'!$C$44) -> 4896457.3 | S9: =IF(N9="","",SUM(O9:R9)/('[1]LOCH Calc COE Calc'!$C$28)) -> 62.281222 | T9: =IF(L9="","",O9/'[1]LOCH Calc COE Calc'!$C$28) -> 58.668137 | U9: =IF(L9="","",P9/'[1]LOCH Calc COE Calc'!$C$28) -> 0.19194107 | V9: =IF(L9="","",Q9/'[1]LOCH Calc COE Calc'!$C$28) -> 3.21 | W9: =IF(L9="","",R9/'[1]LOCH Calc COE Calc'!$C$28) -> 0.21114397
A10: Biomass sorghum | B10: -2.03 | C10: 0.00011776248 | D10: 20.2 | E10: 0.01094 | F10: 0.4 | G10: 0.25 | H10: =B10*(1-G10)*970.2 -> -1477.1295 | L10: =IF('[1]All Data '!BE15="","",'[1]All Data '!BE15) -> 0.055 | M10: =IF('[1]All Data '!BF15="","",'[1]All Data '!BF15) -> 4767.5628 | N10: =IF('[1]All Data '!BB15="","",'[1]All Data '!BC15/'[1]All Data '!BH15) -> 281153.89 | O10: =IF(N10="","",M10*N10) -> 1.3404188e+09 | P10: =IF(M10="","",$C$2*(1-L10)*907.2/0.621371*N10*[1]Transportation!$M$40) -> 4385368.8 | Q10: =IF(L10="","",IF([1]Inputs_Outputs!$B$5="Herbaceous",(LCA!$E$29*'[1]LOCH Calc COE Calc'!$C$28),IF([1]Inputs_Outputs!$B$5="Woody",$E$28*'[1]LOCH Calc COE Calc'!$C$28,IF([1]Inputs_Outputs!$B$5="Paper",(LCA!$E$30*'[1]LOCH Calc COE Calc'!$C$28),IF([1]Inputs_Outputs!$B$5="Forest",LCA!$E$31*'[1]LOCH Calc COE Calc'!$C$28))))) -> 74440334 | R10: =IF(M10="","",$E$2*1000*'[1]LOCH Calc COE Calc'!$C$44) -> 4896457.3 | S10: =IF(N10="","",SUM(O10:R10)/('[1]LOCH Calc COE Calc'!$C$28)) -> 61.411499 | T10: =IF(L10="","",O10/'[1]LOCH Calc COE Calc'!$C$28) -> 57.801251 | U10: =IF(L10="","",P10/'[1]LOCH Calc COE Calc'!$C$28) -> 0.18910493 | V10: =IF(L10="","",Q10/'[1]LOCH Calc COE Calc'!$C$28) -> 3.21 | W10: =IF(L10="","",R10/'[1]LOCH Calc COE Calc'!$C$28) -> 0.21114397
A11: Corn stover | B11: -2.03 | C11: 0.00011776248 | D11: 20.29 | E11: 0.01094 | F11: 0.15 | G11: 0.2 | H11: =B11*(1-G11)*970.2 -> -1575.6048 | L11: =IF('[1]All Data '!BE16="","",'[1]All Data '!BE16) -> 0.055 | M11: =IF('[1]All Data '!BF16="","",'[1]All Data '!BF16) -> 4767.5628 | N11: =IF('[1]All Data '!BB16="","",'[1]All Data '!BC16/'[1]All Data '!BH16) -> 273692.11 | O11: =IF(N11="","",M11*N11) -> 1.3048443e+09 | P11: =IF(M11="","",$C$2*(1-L11)*907.2/0.621371*N11*[1]Transportation!$M$40) -> 4268981.9 | Q11: =IF(L11="","",IF([1]Inputs_Outputs!$B$5="Herbaceous",(LCA!$E$29*'[1]LOCH Calc COE Calc'!$C$28),IF([1]Inputs_Outputs!$B$5="Woody",$E$28*'[1]LOCH Calc COE Calc'!$C$28,IF([1]Inputs_Outputs!$B$5="Paper",(LCA!$E$30*'[1]LOCH Calc COE Calc'!$C$28),IF([1]Inputs_Outputs!$B$5="Forest",LCA!$E$31*'[1]LOCH Calc COE Calc'!$C$28))))) -> 74440334 | R11: =IF(M11="","",$E$2*1000*'[1]LOCH Calc COE Calc'!$C$44) -> 4896457.3 | S11: =IF(N11="","",SUM(O11:R11)/('[1]LOCH Calc COE Calc'!$C$28)) -> 59.872445 | T11: =IF(L11="","",O11/'[1]LOCH Calc COE Calc'!$C$28) -> 56.267215 | U11: =IF(L11="","",P11/'[1]LOCH Calc COE Calc'!$C$28) -> 0.18408611 | V11: =IF(L11="","",Q11/'[1]LOCH Calc COE Calc'!$C$28) -> 3.21 | W11: =IF(L11="","",R11/'[1]LOCH Calc COE Calc'!$C$28) -> 0.21114397
A12: Cotton field residues | B12: -2.03 | C12: 0.00011776248 | D12: 20.29 | E12: 0.01094 | G12: 0.15 | H12: =B12*(1-G12)*970.2 -> -1674.0801 | L12: =IF('[1]All Data '!BE17="","",'[1]All Data '!BE17) -> 0.055 | M12: =IF('[1]All Data '!BF17="","",'[1]All Data '!BF17) -> 4767.5628 | N12: =IF('[1]All Data '!BB17="","",'[1]All Data '!BC17/'[1]All Data '!BH17) -> 269857.11 | O12: =IF(N12="","",M12*N12) -> 1.2865607e+09 | P12: =IF(M12="","",$C$2*(1-L12)*907.2/0.621371*N12*[1]Transportation!$M$40) -> 4209164.5 | Q12: =IF(L12="","",IF([1]Inputs_Outputs!$B$5="Herbaceous",(LCA!$E$29*'[1]LOCH Calc COE Calc'!$C$28),IF([1]Inputs_Outputs!$B$5="Woody",$E$28*'[1]LOCH Calc COE Calc'!$C$28,IF([1]Inputs_Outputs!$B$5="Paper",(LCA!$E$30*'[1]LOCH Calc COE Calc'!$C$28),IF([1]Inputs_Outputs!$B$5="Forest",LCA!$E$31*'[1]LOCH Calc COE Calc'!$C$28))))) -> 74440334 | R12: =IF(M12="","",$E$2*1000*'[1]LOCH Calc COE Calc'!$C$44) -> 4896457.3 | S12: =IF(N12="","",SUM(O12:R12)/('[1]LOCH Calc COE Calc'!$C$28)) -> 59.081444 | T12: =IF(L12="","",O12/'[1]LOCH Calc COE Calc'!$C$28) -> 55.478793 | U12: =IF(L12="","",P12/'[1]LOCH Calc COE Calc'!$C$28) -> 0.18150668 | V12: =IF(L12="","",Q12/'[1]LOCH Calc COE Calc'!$C$28) -> 3.21 | W12: =IF(L12="","",R12/'[1]LOCH Calc COE Calc'!$C$28) -> 0.21114397
A13: Cotton gin trash | B13: -2.03 | C13: 0.00011776248 | D13: 20.29 | E13: 0.01094 | G13: 0.15 | H13: =B13*(1-G13)*970.2 -> -1674.0801 | L13: =IF('[1]All Data '!BE18="","",'[1]All Data '!BE18) -> 0.055 | M13: =IF('[1]All Data '!BF18="","",'[1]All Data '!BF18) -> 4767.5628 | N13: =IF('[1]All Data '!BB18="","",'[1]All Data '!BC18/'[1]All Data '!BH18) -> 296038.12 | O13: =IF(N13="","",M13*N13) -> 1.4113804e+09 | P13: =IF(M13="","",$C$2*(1-L13)*907.2/0.621371*N13*[1]Transportation!$M$40) -> 4617529.5 | Q13: =IF(L13="","",IF([1]Inputs_Outputs!$B$5="Herbaceous",(LCA!$E$29*'[1]LOCH Calc COE Calc'!$C$28),IF([1]Inputs_Outputs!$B$5="Woody",$E$28*'[1]LOCH Calc COE Calc'!$C$28,IF([1]Inputs_Outputs!$B$5="Paper",(LCA!$E$30*'[1]LOCH Calc COE Calc'!$C$28),IF([1]Inputs_Outputs!$B$5="Forest",LCA!$E$31*'[1]LOCH Calc COE Calc'!$C$28))))) -> 74440334 | R13: =IF(M13="","",$E$2*1000*'[1]LOCH Calc COE Calc'!$C$44) -> 4896457.3 | S13: =IF(N13="","",SUM(O13:R13)/('[1]LOCH Calc COE Calc'!$C$28)) -> 64.481498 | T13: =IF(L13="","",O13/'[1]LOCH Calc COE Calc'!$C$28) -> 60.861238 | U13: =IF(L13="","",P13/'[1]LOCH Calc COE Calc'!$C$28) -> 0.19911611 | V13: =IF(L13="","",Q13/'[1]LOCH Calc COE Calc'!$C$28) -> 3.21 | W13: =IF(L13="","",R13/'[1]LOCH Calc COE Calc'!$C$28) -> 0.21114397
A14: Energy cane | B14: -0.44 | C14: 0.00011776248 | D14: 20.2 | E14: 0.01094 | F14: 0.7 | G14: 0.4 | H14: =B14*(1-G14)*970.2 -> -256.1328 | L14: =IF('[1]All Data '!BE19="","",'[1]All Data '!BE19) -> 0.055 | M14: =IF('[1]All Data '!BF19="","",'[1]All Data '!BF19) -> 4767.5628 | N14: =IF('[1]All Data '!BB19="","",'[1]All Data '!BC19/'[1]All Data '!BH19) -> 294851.29 | O14: =IF(N14="","",M14*N14) -> 1.405722e+09 | P14: =IF(M14="","",$C$2*(1-L14)*907.2/0.621371*N14*[1]Transportation!$M$40) -> 4599017.4 | Q14: =IF(L14="","",IF([1]Inputs_Outputs!$B$5="Herbaceous",(LCA!$E$29*'[1]LOCH Calc COE Calc'!$C$28),IF([1]Inputs_Outputs!$B$5="Woody",$E$28*'[1]LOCH Calc COE Calc'!$C$28,IF([1]Inputs_Outputs!$B$5="Paper",(LCA!$E$30*'[1]LOCH Calc COE Calc'!$C$28),IF([1]Inputs_Outputs!$B$5="Forest",LCA!$E$31*'[1]LOCH Calc COE Calc'!$C$28))))) -> 74440334 | R14: =IF(M14="","",$E$2*1000*'[1]LOCH Calc COE Calc'!$C$44) -> 4896457.3 | S14: =IF(N14="","",SUM(O14:R14)/('[1]LOCH Calc COE Calc'!$C$28)) -> 64.236703 | T14: =IF(L14="","",O14/'[1]LOCH Calc COE Calc'!$C$28) -> 60.617241 | U14: =IF(L14="","",P14/'[1]LOCH Calc COE Calc'!$C$28) -> 0.19831783 | V14: =IF(L14="","",Q14/'[1]LOCH Calc COE Calc'!$C$28) -> 3.21 | W14: =IF(L14="","",R14/'[1]LOCH Calc COE Calc'!$C$28) -> 0.21114397
A15: Miscanthus | B15: -2.03 | C15: 0.00011776248 | D15: 20.2 | E15: 0.01094 | G15: 0.15 | H15: =B15*(1-G15)*970.2 -> -1674.0801 | L15: =IF('[1]All Data '!BE20="","",'[1]All Data '!BE20) -> 0.055 | M15: =IF('[1]All Data '!BF20="","",'[1]All Data '!BF20) -> 4767.5628 | N15: =IF('[1]All Data '!BB20="","",'[1]All Data '!BC20/'[1]All Data '!BH20) -> 292725.86 | O15: =IF(N15="","",M15*N15) -> 1.3955889e+09 | P15: =IF(M15="","",$C$2*(1-L15)*907.2/0.621371*N15*[1]Transportation!$M$40) -> 4565865.5 | Q15: =IF(L15="","",IF([1]Inputs_Outputs!$B$5="Herbaceous",(LCA!$E$29*'[1]LOCH Calc COE Calc'!$C$28),IF([1]Inputs_Outputs!$B$5="Woody",$E$28*'[1]LOCH Calc COE Calc'!$C$28,IF([1]Inputs_Outputs!$B$5="Paper",(LCA!$E$30*'[1]LOCH Calc COE Calc'!$C$28),IF([1]Inputs_Outputs!$B$5="Forest",LCA!$E$31*'[1]LOCH Calc COE Calc'!$C$28))))) -> 74440334 | R15: =IF(M15="","",$E$2*1000*'[1]LOCH Calc COE Calc'!$C$44) -> 4896457.3 | S15: =IF(N15="","",SUM(O15:R15)/('[1]LOCH Calc COE Calc'!$C$28)) -> 63.798315 | T15: =IF(L15="","",O15/'[1]LOCH Calc COE Calc'!$C$28) -> 60.180283 | U15: =IF(L15="","",P15/'[1]LOCH Calc COE Calc'!$C$28) -> 0.19688827 | V15: =IF(L15="","",Q15/'[1]LOCH Calc COE Calc'!$C$28) -> 3.21 | W15: =IF(L15="","",R15/'[1]LOCH Calc COE Calc'!$C$28) -> 0.21114397
A16: Oats straw | B16: -2.03 | C16: 0.00011776248 | D16: 20.2 | E16: 0.01094 | G16: 0.18 | H16: =B16*(1-G16)*970.2 -> -1614.9949 | L16: =IF('[1]All Data '!BE21="","",'[1]All Data '!BE21) -> 0.055 | M16: =IF('[1]All Data '!BF21="","",'[1]All Data '!BF21) -> 4767.5628 | N16: =IF('[1]All Data '!BB21="","",'[1]All Data '!BC21/'[1]All Data '!BH21) -> 282051.14 | O16: =IF(N16="","",M16*N16) -> 1.3446965e+09 | P16: =IF(M16="","",$C$2*(1-L16)*907.2/0.621371*N16*[1]Transportation!$M$40) -> 4399364 | Q16: =IF(L16="","",IF([1]Inputs_Outputs!$B$5="Herbaceous",(LCA!$E$29*'[1]LOCH Calc COE Calc'!$C$28),IF([1]Inputs_Outputs!$B$5="Woody",$E$28*'[1]LOCH Calc COE Calc'!$C$28,IF([1]Inputs_Outputs!$B$5="Paper",(LCA!$E$30*'[1]LOCH Calc COE Calc'!$C$28),IF([1]Inputs_Outputs!$B$5="Forest",LCA!$E$31*'[1]LOCH Calc COE Calc'!$C$28))))) -> 74440334 | R16: =IF(M16="","",$E$2*1000*'[1]LOCH Calc COE Calc'!$C$44) -> 4896457.3 | S16: =IF(N16="","",SUM(O16:R16)/('[1]LOCH Calc COE Calc'!$C$28)) -> 61.596566 | T16: =IF(L16="","",O16/'[1]LOCH Calc COE Calc'!$C$28) -> 57.985713 | U16: =IF(L16="","",P16/'[1]LOCH Calc COE Calc'!$C$28) -> 0.18970842 | V16: =IF(L16="","",Q16/'[1]LOCH Calc COE Calc'!$C$28) -> 3.21 | W16: =IF(L16="","",R16/'[1]LOCH Calc COE Calc'!$C$28) -> 0.21114397
A17: Sorghum stubble | B17: -2.03 | C17: 0.00011776248 | D17: 20.2 | E17: 0.01094 | G17: 0.4 | H17: =B17*(1-G17)*970.2 -> -1181.7036 | L17: =IF('[1]All Data '!BE22="","",'[1]All Data '!BE22) -> 0.055 | M17: =IF('[1]All Data '!BF22="","",'[1]All Data '!BF22) -> 4767.5628 | N17: =IF('[1]All Data '!BB22="","",'[1]All Data '!BC22/'[1]All Data '!BH22) -> 281652.57 | O17: =IF(N17="","",M17*N17) -> 1.3427963e+09 | P17: =IF(M17="","",$C$2*(1-L17)*907.2/0.621371*N17*[1]Transportation!$M$40) -> 4393147.1 | Q17: =IF(L17="","",IF([1]Inputs_Outputs!$B$5="Herbaceous",(LCA!$E$29*'[1]LOCH Calc COE Calc'!$C$28),IF([1]Inputs_Outputs!$B$5="Woody",$E$28*'[1]LOCH Calc COE Calc'!$C$28,IF([1]Inputs_Outputs!$B$5="Paper",(LCA!$E$30*'[1]LOCH Calc COE Calc'!$C$28),IF([1]Inputs_Outputs!$B$5="Forest",LCA!$E$31*'[1]LOCH Calc COE Calc'!$C$28))))) -> 74440334 | R17: =IF(M17="","",$E$2*1000*'[1]LOCH Calc COE Calc'!$C$44) -> 4896457.3 | S17: =IF(N17="","",SUM(O17:R17)/('[1]LOCH Calc COE Calc'!$C$28)) -> 61.514357 | T17: =IF(L17="","",O17/'[1]LOCH Calc COE Calc'!$C$28) -> 57.903773 | U17: =IF(L17="","",P17/'[1]LOCH Calc COE Calc'!$C$28) -> 0.18944034 | V17: =IF(L17="","",Q17/'[1]LOCH Calc COE Calc'!$C$28) -> 3.21 | W17: =IF(L17="","",R17/'[1]LOCH Calc COE Calc'!$C$28) -> 0.21114397
A18: Switchgrass | B18: -1.96 | C18: 0.00011776248 | D18: 20.2 | E18: 0.01094 | F18: 0.15 | G18: 0.15 | H18: =B18*(1-G18)*970.2 -> -1616.3532 | L18: =IF('[1]All Data '!BE23="","",'[1]All Data '!BE23) -> 0.055 | M18: =IF('[1]All Data '!BF23="","",'[1]All Data '!BF23) -> 4767.5628 | N18: =IF('[1]All Data '!BB23="","",'[1]All Data '!BC23/'[1]All Data '!BH23) -> 277617 | O18: =IF(N18="","",M18*N18) -> 1.3235565e+09 | P18: =IF(M18="","",$C$2*(1-L18)*907.2/0.621371*N18*[1]Transportation!$M$40) -> 4330201.3 | Q18: =IF(L18="","",IF([1]Inputs_Outputs!$B$5="Herbaceous",(LCA!$E$29*'[1]LOCH Calc COE Calc'!$C$28),IF([1]Inputs_Outputs!$B$5="Woody",$E$28*'[1]LOCH Calc COE Calc'!$C$28,IF([1]Inputs_Outputs!$B$5="Paper",(LCA!$E$30*'[1]LOCH Calc COE Calc'!$C$28),IF([1]Inputs_Outputs!$B$5="Forest",LCA!$E$31*'[1]LOCH Calc COE Calc'!$C$28))))) -> 74440334 | R18: =IF(M18="","",$E$2*1000*'[1]LOCH Calc COE Calc'!$C$44) -> 4896457.3 | S18: =IF(N18="","",SUM(O18:R18)/('[1]LOCH Calc COE Calc'!$C$28)) -> 60.681986 | T18: =IF(L18="","",O18/'[1]LOCH Calc COE Calc'!$C$28) -> 57.074116 | U18: =IF(L18="","",P18/'[1]LOCH Calc COE Calc'!$C$28) -> 0.186726 | V18: =IF(L18="","",Q18/'[1]LOCH Calc COE Calc'!$C$28) -> 3.21 | W18: =IF(L18="","",R18/'[1]LOCH Calc COE Calc'!$C$28) -> 0.21114397
A19: Wheat straw | B19: -2.03 | C19: 0.00011776248 | D19: 20.2 | E19: 0.01094 | G19: 0.16 | H19: =B19*(1-G19)*970.2 -> -1654.385 | L19: =IF('[1]All Data '!BE24="","",'[1]All Data '!BE24) -> 0.055 | M19: =IF('[1]All Data '!BF24="","",'[1]All Data '!BF24) -> 4767.5628 | N19: =IF('[1]All Data '!BB24="","",'[1]All Data '!BC24/'[1]All Data '!BH24) -> 273869.29 | O19: =IF(N19="","",M19*N19) -> 1.305689e+09 | P19: =IF(M19="","",$C$2*(1-L19)*907.2/0.621371*N19*[1]Transportation!$M$40) -> 4271745.4 | Q19: =IF(L19="","",IF([1]Inputs_Outputs!$B$5="Herbaceous",(LCA!$E$29*'[1]LOCH Calc COE Calc'!$C$28),IF([1]Inputs_Outputs!$B$5="Woody",$E$28*'[1]LOCH Calc COE Calc'!$C$28,IF([1]Inputs_Outputs!$B$5="Paper",(LCA!$E$30*'[1]LOCH Calc COE Calc'!$C$28),IF([1]Inputs_Outputs!$B$5="Forest",LCA!$E$31*'[1]LOCH Calc COE Calc'!$C$28))))) -> 74440334 | R19: =IF(M19="","",$E$2*1000*'[1]LOCH Calc COE Calc'!$C$44) -> 4896457.3 | S19: =IF(N19="","",SUM(O19:R19)/('[1]LOCH Calc COE Calc'!$C$28)) -> 59.908989 | T19: =IF(L19="","",O19/'[1]LOCH Calc COE Calc'!$C$28) -> 56.303639 | U19: =IF(L19="","",P19/'[1]LOCH Calc COE Calc'!$C$28) -> 0.18420528 | V19: =IF(L19="","",Q19/'[1]LOCH Calc COE Calc'!$C$28) -> 3.21 | W19: =IF(L19="","",R19/'[1]LOCH Calc COE Calc'!$C$28) -> 0.21114397
A20: Plastic | B20: 2 | C20: 0.00011776248 | D20: 3.21 | E20: 0.01094 | G20: 0.02 | H20: =B20*(1-G20)*970.2 -> 1901.592 | L20: =IF('[1]All Data '!BE25="","",'[1]All Data '!BE25) -> 0.055 | M20: =IF('[1]All Data '!BF25="","",'[1]All Data '!BF25) -> 4767.5628 | N20: =IF('[1]All Data '!BB25="","",'[1]All Data '!BC25/'[1]All Data '!BH25) -> 311140.33 | O20: =IF(N20="","",M20*N20) -> 1.4833811e+09 | P20: =IF(M20="","",$C$2*(1-L20)*907.2/0.621371*N20*[1]Transportation!$M$40) -> 4853090 | Q20: =IF(L20="","",IF([1]Inputs_Outputs!$B$5="Herbaceous",(LCA!$E$29*'[1]LOCH Calc COE Calc'!$C$28),IF([1]Inputs_Outputs!$B$5="Woody",$E$28*'[1]LOCH Calc COE Calc'!$C$28,IF([1]Inputs_Outputs!$B$5="Paper",(LCA!$E$30*'[1]LOCH Calc COE Calc'!$C$28),IF([1]Inputs_Outputs!$B$5="Forest",LCA!$E$31*'[1]LOCH Calc COE Calc'!$C$28))))) -> 74440334 | R20: =IF(M20="","",$E$2*1000*'[1]LOCH Calc COE Calc'!$C$44) -> 4896457.3 | S20: =IF(N20="","",SUM(O20:R20)/('[1]LOCH Calc COE Calc'!$C$28)) -> 67.596456 | T20: =IF(L20="","",O20/'[1]LOCH Calc COE Calc'!$C$28) -> 63.966038 | U20: =IF(L20="","",P20/'[1]LOCH Calc COE Calc'!$C$28) -> 0.2092739 | V20: =IF(L20="","",Q20/'[1]LOCH Calc COE Calc'!$C$28) -> 3.21 | W20: =IF(L20="","",R20/'[1]LOCH Calc COE Calc'!$C$28) -> 0.21114397
A21: Paper/Cardboard | B21: 5.2 | C21: 0.00011776248 | D21: 3.21 | E21: 0.01094 | G21: 0.055 | H21: =B21*(1-G21)*970.2 -> 4767.5628 | L21: =IF('[1]All Data '!BE26="","",'[1]All Data '!BE26) -> 0.055 | M21: =IF('[1]All Data '!BF26="","",'[1]All Data '!BF26) -> 4767.5628 | N21: =IF('[1]All Data '!BB26="","",'[1]All Data '!BC26/'[1]All Data '!BH26) -> 308532.33 | O21: =IF(N21="","",M21*N21) -> 1.4709473e+09 | P21: =IF(M21="","",$C$2*(1-L21)*907.2/0.621371*N21*[1]Transportation!$M$40) -> 4812411 | Q21: =IF(L21="","",IF([1]Inputs_Outputs!$B$5="Herbaceous",(LCA!$E$29*'[1]LOCH Calc COE Calc'!$C$28),IF([1]Inputs_Outputs!$B$5="Woody",$E$28*'[1]LOCH Calc COE Calc'!$C$28,IF([1]Inputs_Outputs!$B$5="Paper",(LCA!$E$30*'[1]LOCH Calc COE Calc'!$C$28),IF([1]Inputs_Outputs!$B$5="Forest",LCA!$E$31*'[1]LOCH Calc COE Calc'!$C$28))))) -> 74440334 | R21: =IF(M21="","",$E$2*1000*'[1]LOCH Calc COE Calc'!$C$44) -> 4896457.3 | S21: =IF(N21="","",SUM(O21:R21)/('[1]LOCH Calc COE Calc'!$C$28)) -> 67.058534 | T21: =IF(L21="","",O21/'[1]LOCH Calc COE Calc'!$C$28) -> 63.42987 | U21: =IF(L21="","",P21/'[1]LOCH Calc COE Calc'!$C$28) -> 0.20751975 | V21: =IF(L21="","",Q21/'[1]LOCH Calc COE Calc'!$C$28) -> 3.21 | W21: =IF(L21="","",R21/'[1]LOCH Calc COE Calc'!$C$28) -> 0.21114397
A22: MSW | B22: 5.2 | C22: 0.00011776248 | D22: 3.21 | E22: 0.01094 | G22: 0.055 | H22: =B22*(1-G22)*970.2 -> 4767.5628 | L22: =IF('[1]All Data '!BE27="","",'[1]All Data '!BE27) -> 0.055 | M22: =IF('[1]All Data '!BF27="","",'[1]All Data '!BF27) -> 4767.5628 | N22: =IF('[1]All Data '!BB27="","",'[1]All Data '!BC27/'[1]All Data '!BH27) -> 293731 | O22: =IF(N22="","",M22*N22) -> 1.400381e+09 | P22: =IF(M22="","",$C$2*(1-L22)*907.2/0.621371*N22*[1]Transportation!$M$40) -> 4581543.5 | Q22: =IF(L22="","",IF([1]Inputs_Outputs!$B$5="Herbaceous",(LCA!$E$29*'[1]LOCH Calc COE Calc'!$C$28),IF([1]Inputs_Outputs!$B$5="Woody",$E$28*'[1]LOCH Calc COE Calc'!$C$28,IF([1]Inputs_Outputs!$B$5="Paper",(LCA!$E$30*'[1]LOCH Calc COE Calc'!$C$28),IF([1]Inputs_Outputs!$B$5="Forest",LCA!$E$31*'[1]LOCH Calc COE Calc'!$C$28))))) -> 74440334 | R22: =IF(M22="","",$E$2*1000*'[1]LOCH Calc COE Calc'!$C$44) -> 4896457.3 | S22: =IF(N22="","",SUM(O22:R22)/('[1]LOCH Calc COE Calc'!$C$28)) -> 64.005634 | T22: =IF(L22="","",O22/'[1]LOCH Calc COE Calc'!$C$28) -> 60.386926 | U22: =IF(L22="","",P22/'[1]LOCH Calc COE Calc'!$C$28) -> 0.19756433 | V22: =IF(L22="","",Q22/'[1]LOCH Calc COE Calc'!$C$28) -> 3.21 | W22: =IF(L22="","",R22/'[1]LOCH Calc COE Calc'!$C$28) -> 0.21114397
A23: Fire reduction thinnings | B23: =B6 -> -1.33 | C23: 0.00011776248 | D23: =D6 -> 20.22 | E23: 0.01094 | G23: 0.54 | H23: =B23*(1-G23)*970.2 -> -593.56836 | L23: =IF('[1]All Data '!BE28="","",'[1]All Data '!BE28) -> 0.055 | M23: =IF('[1]All Data '!BF28="","",'[1]All Data '!BF28) -> 4767.5628 | N23: =IF('[1]All Data '!BB28="","",'[1]All Data '!BC28/'[1]All Data '!BH28) -> 286143.5 | O23: =IF(N23="","",M23*N23) -> 1.3642071e+09 | P23: =IF(M23="","",$C$2*(1-L23)*907.2/0.621371*N23*[1]Transportation!$M$40) -> 4463195.5 | Q23: =IF(L23="","",IF([1]Inputs_Outputs!$B$5="Herbaceous",(LCA!$E$29*'[1]LOCH Calc COE Calc'!$C$28),IF([1]Inputs_Outputs!$B$5="Woody",$E$28*'[1]LOCH Calc COE Calc'!$C$28,IF([1]Inputs_Outputs!$B$5="Paper",(LCA!$E$30*'[1]LOCH Calc COE Calc'!$C$28),IF([1]Inputs_Outputs!$B$5="Forest",LCA!$E$31*'[1]LOCH Calc COE Calc'!$C$28))))) -> 74440334 | R23: =IF(M23="","",$E$2*1000*'[1]LOCH Calc COE Calc'!$C$44) -> 4896457.3 | S23: =IF(N23="","",SUM(O23:R23)/('[1]LOCH Calc COE Calc'!$C$28)) -> 62.440649 | T23: =IF(L23="","",O23/'[1]LOCH Calc COE Calc'!$C$28) -> 58.827044 | U23: =IF(L23="","",P23/'[1]LOCH Calc COE Calc'!$C$28) -> 0.19246095 | V23: =IF(L23="","",Q23/'[1]LOCH Calc COE Calc'!$C$28) -> 3.21 | W23: =IF(L23="","",R23/'[1]LOCH Calc COE Calc'!$C$28) -> 0.21114397
A24: Forest processing waste | B24: =B6 -> -1.33 | C24: 0.00011776248 | D24: =D6 -> 20.22 | E24: 0.01094 | G24: 0.54 | H24: =B24*(1-G24)*970.2 -> -593.56836 | L24: =IF('[1]All Data '!BE29="","",'[1]All Data '!BE29) -> 0.055 | M24: =IF('[1]All Data '!BF29="","",'[1]All Data '!BF29) -> 4767.5628 | N24: =IF('[1]All Data '!BB29="","",'[1]All Data '!BC29/'[1]All Data '!BH29) -> 283579.33 | O24: =IF(N24="","",M24*N24) -> 1.3519823e+09 | P24: =IF(M24="","",$C$2*(1-L24)*907.2/0.621371*N24*[1]Transportation!$M$40) -> 4423200.3 | Q24: =IF(L24="","",IF([1]Inputs_Outputs!$B$5="Herbaceous",(LCA!$E$29*'[1]LOCH Calc COE Calc'!$C$28),IF([1]Inputs_Outputs!$B$5="Woody",$E$28*'[1]LOCH Calc COE Calc'!$C$28,IF([1]Inputs_Outputs!$B$5="Paper",(LCA!$E$30*'[1]LOCH Calc COE Calc'!$C$28),IF([1]Inputs_Outputs!$B$5="Forest",LCA!$E$31*'[1]LOCH Calc COE Calc'!$C$28))))) -> 74440334 | R24: =IF(M24="","",$E$2*1000*'[1]LOCH Calc COE Calc'!$C$44) -> 4896457.3 | S24: =IF(N24="","",SUM(O24:R24)/('[1]LOCH Calc COE Calc'!$C$28)) -> 61.911768 | T24: =IF(L24="","",O24/'[1]LOCH Calc COE Calc'!$C$28) -> 58.299888 | U24: =IF(L24="","",P24/'[1]LOCH Calc COE Calc'!$C$28) -> 0.19073629 | V24: =IF(L24="","",Q24/'[1]LOCH Calc COE Calc'!$C$28) -> 3.21 | W24: =IF(L24="","",R24/'[1]LOCH Calc COE Calc'!$C$28) -> 0.21114397
A25: Logging residues | B25: =B6 -> -1.33 | C25: 0.00011776248 | D25: =D6 -> 20.22 | E25: 0.01094 | G25: 0.54 | H25: =B25*(1-G25)*970.2 -> -593.56836 | L25: =IF('[1]All Data '!BE30="","",'[1]All Data '!BE30) -> 0.055 | M25: =IF('[1]All Data '!BF30="","",'[1]All Data '!BF30) -> 4767.5628 | N25: =IF('[1]All Data '!BB30="","",'[1]All Data '!BC30/'[1]All Data '!BH30) -> 269797.17 | O25: =IF(N25="","",M25*N25) -> 1.2862749e+09 | P25: =IF(M25="","",$C$2*(1-L25)*907.2/0.621371*N25*[1]Transportation!$M$40) -> 4208229.5 | Q25: =IF(L25="","",IF([1]Inputs_Outputs!$B$5="Herbaceous",(LCA!$E$29*'[1]LOCH Calc COE Calc'!$C$28),IF([1]Inputs_Outputs!$B$5="Woody",$E$28*'[1]LOCH Calc COE Calc'!$C$28,IF([1]Inputs_Outputs!$B$5="Paper",(LCA!$E$30*'[1]LOCH Calc COE Calc'!$C$28),IF([1]Inputs_Outputs!$B$5="Forest",LCA!$E$31*'[1]LOCH Calc COE Calc'!$C$28))))) -> 74440334 | R25: =IF(M25="","",$E$2*1000*'[1]LOCH Calc COE Calc'!$C$44) -> 4896457.3 | S25: =IF(N25="","",SUM(O25:R25)/('[1]LOCH Calc COE Calc'!$C$28)) -> 59.06908 | T25: =IF(L25="","",O25/'[1]LOCH Calc COE Calc'!$C$28) -> 55.46647 | U25: =IF(L25="","",P25/'[1]LOCH Calc COE Calc'!$C$28) -> 0.18146636 | V25: =IF(L25="","",Q25/'[1]LOCH Calc COE Calc'!$C$28) -> 3.21 | W25: =IF(L25="","",R25/'[1]LOCH Calc COE Calc'!$C$28) -> 0.21114397
A26: Other forest waste | B26: =B6 -> -1.33 | C26: 0.00011776248 | D26: =D6 -> 20.22 | E26: 0.01094 | G26: 0.54 | H26: =B26*(1-G26)*970.2 -> -593.56836 | L26: =IF('[1]All Data '!BE31="","",'[1]All Data '!BE31) -> 0.055 | M26: =IF('[1]All Data '!BF31="","",'[1]All Data '!BF31) -> 4767.5628 | N26: =IF('[1]All Data '!BB31="","",'[1]All Data '!BC31/'[1]All Data '!BH31) -> 269641.5 | O26: =IF(N26="","",M26*N26) -> 1.2855328e+09 | P26: =IF(M26="","",$C$2*(1-L26)*907.2/0.621371*N26*[1]Transportation!$M$40) -> 4205801.4 | Q26: =IF(L26="","",IF([1]Inputs_Outputs!$B$5="Herbaceous",(LCA!$E$29*'[1]LOCH Calc COE Calc'!$C$28),IF([1]Inputs_Outputs!$B$5="Woody",$E$28*'[1]LOCH Calc COE Calc'!$C$28,IF([1]Inputs_Outputs!$B$5="Paper",(LCA!$E$30*'[1]LOCH Calc COE Calc'!$C$28),IF([1]Inputs_Outputs!$B$5="Forest",LCA!$E$31*'[1]LOCH Calc COE Calc'!$C$28))))) -> 74440334 | R26: =IF(M26="","",$E$2*1000*'[1]LOCH Calc COE Calc'!$C$44) -> 4896457.3 | S26: =IF(N26="","",SUM(O26:R26)/('[1]LOCH Calc COE Calc'!$C$28)) -> 59.036972 | T26: =IF(L26="","",O26/'[1]LOCH Calc COE Calc'!$C$28) -> 55.434467 | U26: =IF(L26="","",P26/'[1]LOCH Calc COE Calc'!$C$28) -> 0.18136166 | V26: =IF(L26="","",Q26/'[1]LOCH Calc COE Calc'!$C$28) -> 3.21 | W26: =IF(L26="","",R26/'[1]LOCH Calc COE Calc'!$C$28) -> 0.21114397
A27: Small diameter trees | B27: =B4 -> -1.33 | C27: 0.00011776248 | D27: =D4 -> 20.22 | E27: 0.01094 | G27: 0.54 | H27: =B27*(1-G27)*970.2 -> -593.56836 | L27: =IF('[1]All Data '!BE32="","",'[1]All Data '!BE32) -> 0.055 | M27: =IF('[1]All Data '!BF32="","",'[1]All Data '!BF32) -> 4767.5628 | N27: =IF('[1]All Data '!BB32="","",'[1]All Data '!BC32/'[1]All Data '!BH32) -> 317007.4 | O27: =IF(N27="","",M27*N27) -> 1.5113527e+09 | P27: =IF(M27="","",$C$2*(1-L27)*907.2/0.621371*N27*[1]Transportation!$M$40) -> 4944603 | Q27: =IF(L27="","",IF([1]Inputs_Outputs!$B$5="Herbaceous",(LCA!$E$29*'[1]LOCH Calc COE Calc'!$C$28),IF([1]Inputs_Outputs!$B$5="Woody",$E$28*'[1]LOCH Calc COE Calc'!$C$28,IF([1]Inputs_Outputs!$B$5="Paper",(LCA!$E$30*'[1]LOCH Calc COE Calc'!$C$28),IF([1]Inputs_Outputs!$B$5="Forest",LCA!$E$31*'[1]LOCH Calc COE Calc'!$C$28))))) -> 74440334 | R27: =IF(M27="","",$E$2*1000*'[1]LOCH Calc COE Calc'!$C$44) -> 4896457.3 | S27: =IF(N27="","",SUM(O27:R27)/('[1]LOCH Calc COE Calc'!$C$28)) -> 68.806588 | T27: =IF(L27="","",O27/'[1]LOCH Calc COE Calc'!$C$28) -> 65.172224 | U27: =IF(L27="","",P27/'[1]LOCH Calc COE Calc'!$C$28) -> 0.2132201 | V27: =IF(L27="","",Q27/'[1]LOCH Calc COE Calc'!$C$28) -> 3.21 | W27: =IF(L27="","",R27/'[1]LOCH Calc COE Calc'!$C$28) -> 0.21114397
A28: * All biomass types filled out included grinding, torrefaction (with natural gas), and pelletization | D28: Average Gasification GWP Woody | E28: =AVERAGE(D2,D3,D4,D5,D6,D7,D8) -> 20.212857 | F28: =AVERAGE(G2:G8) -> 0.50185714 | L28: =IF('[1]All Data '!BE33="","",'[1]All Data '!BE33) -> 0.055 | M28: =IF('[1]All Data '!BF33="","",'[1]All Data '!BF33) -> 4767.5628 | N28: =IF('[1]All Data '!BB33="","",'[1]All Data '!BC33/'[1]All Data '!BH33) -> 313354 | O28: =IF(N28="","",M28*N28) -> 1.4939349e+09 | P28: =IF(M28="","",$C$2*(1-L28)*907.2/0.621371*N28*[1]Transportation!$M$40) -> 4887618.2 | Q28: =IF(L28="","",IF([1]Inputs_Outputs!$B$5="Herbaceous",(LCA!$E$29*'[1]LOCH Calc COE Calc'!$C$28),IF([1]Inputs_Outputs!$B$5="Woody",$E$28*'[1]LOCH Calc COE Calc'!$C$28,IF([1]Inputs_Outputs!$B$5="Paper",(LCA!$E$30*'[1]LOCH Calc COE Calc'!$C$28),IF([1]Inputs_Outputs!$B$5="Forest",LCA!$E$31*'[1]LOCH Calc COE Calc'!$C$28))))) -> 74440334 | R28: =IF(M28="","",$E$2*1000*'[1]LOCH Calc COE Calc'!$C$44) -> 4896457.3 | S28: =IF(N28="","",SUM(O28:R28)/('[1]LOCH Calc COE Calc'!$C$28)) -> 68.053043 | T28: =IF(L28="","",O28/'[1]LOCH Calc COE Calc'!$C$28) -> 64.421137 | U28: =IF(L28="","",P28/'[1]LOCH Calc COE Calc'!$C$28) -> 0.21076281 | V28: =IF(L28="","",Q28/'[1]LOCH Calc COE Calc'!$C$28) -> 3.21 | W28: =IF(L28="","",R28/'[1]LOCH Calc COE Calc'!$C$28) -> 0.21114397
A29: LCA: Transport-Storage CO2 | D29: Average Gasification GWP herb | E29: =AVERAGE(D9:D19) -> 20.224545 | F29: =AVERAGE(G9:G19) -> 0.22636364 | L29: =IF('[1]All Data '!BE34="","",'[1]All Data '!BE34) -> 0.055 | M29: =IF('[1]All Data '!BF34="","",'[1]All Data '!BF34) -> 4767.5628 | N29: =IF('[1]All Data '!BB34="","",'[1]All Data '!BC34/'[1]All Data '!BH34) -> 312694.2 | O29: =IF(N29="","",M29*N29) -> 1.4907892e+09 | P29: =IF(M29="","",$C$2*(1-L29)*907.2/0.621371*N29*[1]Transportation!$M$40) -> 4877326.8 | Q29: =IF(L29="","",IF([1]Inputs_Outputs!$B$5="Herbaceous",(LCA!$E$29*'[1]LOCH Calc COE Calc'!$C$28),IF([1]Inputs_Outputs!$B$5="Woody",$E$28*'[1]LOCH Calc COE Calc'!$C$28,IF([1]Inputs_Outputs!$B$5="Paper",(LCA!$E$30*'[1]LOCH Calc COE Calc'!$C$28),IF([1]Inputs_Outputs!$B$5="Forest",LCA!$E$31*'[1]LOCH Calc COE Calc'!$C$28))))) -> 74440334 | R29: =IF(M29="","",$E$2*1000*'[1]LOCH Calc COE Calc'!$C$44) -> 4896457.3 | S29: =IF(N29="","",SUM(O29:R29)/('[1]LOCH Calc COE Calc'!$C$28)) -> 67.916954 | T29: =IF(L29="","",O29/'[1]LOCH Calc COE Calc'!$C$28) -> 64.285491 | U29: =IF(L29="","",P29/'[1]LOCH Calc COE Calc'!$C$28) -> 0.21031903 | V29: =IF(L29="","",Q29/'[1]LOCH Calc COE Calc'!$C$28) -> 3.21 | W29: =IF(L29="","",R29/'[1]LOCH Calc COE Calc'!$C$28) -> 0.21114397
D30: Average Gasification GWP paper, cardboard, plastics | E30: =AVERAGE(D21:D22) -> 3.21 | F30: =AVERAGE(G21:G22) -> 0.055 | L30: =IF('[1]All Data '!BE35="","",'[1]All Data '!BE35) -> 0.055 | M30: =IF('[1]All Data '!BF35="","",'[1]All Data '!BF35) -> 4767.5628 | N30: =IF('[1]All Data '!BB35="","",'[1]All Data '!BC35/'[1]All Data '!BH35) -> 311520.2 | O30: =IF(N30="","",M30*N30) -> 1.4851921e+09 | P30: =IF(M30="","",$C$2*(1-L30)*907.2/0.621371*N30*[1]Transportation!$M$40) -> 4859015 | Q30: =IF(L30="","",IF([1]Inputs_Outputs!$B$5="Herbaceous",(LCA!$E$29*'[1]LOCH Calc COE Calc'!$C$28),IF([1]Inputs_Outputs!$B$5="Woody",$E$28*'[1]LOCH Calc COE Calc'!$C$28,IF([1]Inputs_Outputs!$B$5="Paper",(LCA!$E$30*'[1]LOCH Calc COE Calc'!$C$28),IF([1]Inputs_Outputs!$B$5="Forest",LCA!$E$31*'[1]LOCH Calc COE Calc'!$C$28))))) -> 74440334 | R30: =IF(M30="","",$E$2*1000*'[1]LOCH Calc COE Calc'!$C$44) -> 4896457.3 | S30: =IF(N30="","",SUM(O30:R30)/('[1]LOCH Calc COE Calc'!$C$28)) -> 67.674807 | T30: =IF(L30="","",O30/'[1]LOCH Calc COE Calc'!$C$28) -> 64.044133 | U30: =IF(L30="","",P30/'[1]LOCH Calc COE Calc'!$C$28) -> 0.2095294 | V30: =IF(L30="","",Q30/'[1]LOCH Calc COE Calc'!$C$28) -> 3.21 | W30: =IF(L30="","",R30/'[1]LOCH Calc COE Calc'!$C$28) -> 0.21114397
A31: Plastic = LDPE | D31: Average Gasification GWP forest | E31: =AVERAGE(D23:D27) -> 20.22 | F31: =AVERAGE(G23:G27) -> 0.54 | L31: =IF('[1]All Data '!BE36="","",'[1]All Data '!BE36) -> 0.055 | M31: =IF('[1]All Data '!BF36="","",'[1]All Data '!BF36) -> 4767.5628 | N31: =IF('[1]All Data '!BB36="","",'[1]All Data '!BC36/'[1]All Data '!BH36) -> 310525.2 | O31: =IF(N31="","",M31*N31) -> 1.4804484e+09 | P31: =IF(M31="","",$C$2*(1-L31)*907.2/0.621371*N31*[1]Transportation!$M$40) -> 4843495.3 | Q31: =IF(L31="","",IF([1]Inputs_Outputs!$B$5="Herbaceous",(LCA!$E$29*'[1]LOCH Calc COE Calc'!$C$28),IF([1]Inputs_Outputs!$B$5="Woody",$E$28*'[1]LOCH Calc COE Calc'!$C$28,IF([1]Inputs_Outputs!$B$5="Paper",(LCA!$E$30*'[1]LOCH Calc COE Calc'!$C$28),IF([1]Inputs_Outputs!$B$5="Forest",LCA!$E$31*'[1]LOCH Calc COE Calc'!$C$28))))) -> 74440334 | R31: =IF(M31="","",$E$2*1000*'[1]LOCH Calc COE Calc'!$C$44) -> 4896457.3 | S31: =IF(N31="","",SUM(O31:R31)/('[1]LOCH Calc COE Calc'!$C$28)) -> 67.46958 | T31: =IF(L31="","",O31/'[1]LOCH Calc COE Calc'!$C$28) -> 63.839575 | U31: =IF(L31="","",P31/'[1]LOCH Calc COE Calc'!$C$28) -> 0.20886016 | V31: =IF(L31="","",Q31/'[1]LOCH Calc COE Calc'!$C$28) -> 3.21 | W31: =IF(L31="","",R31/'[1]LOCH Calc COE Calc'!$C$28) -> 0.21114397
A32: Paper= newspaper mix | L32: =IF('[1]All Data '!BE37="","",'[1]All Data '!BE37) -> 0.055 | M32: =IF('[1]All Data '!BF37="","",'[1]All Data '!BF37) -> 4767.5628 | N32: =IF('[1]All Data '!BB37="","",'[1]All Data '!BC37/'[1]All Data '!BH37) -> 310344.8 | O32: =IF(N32="","",M32*N32) -> 1.4795883e+09 | P32: =IF(M32="","",$C$2*(1-L32)*907.2/0.621371*N32*[1]Transportation!$M$40) -> 4840681.4 | Q32: =IF(L32="","",IF([1]Inputs_Outputs!$B$5="Herbaceous",(LCA!$E$29*'[1]LOCH Calc COE Calc'!$C$28),IF([1]Inputs_Outputs!$B$5="Woody",$E$28*'[1]LOCH Calc COE Calc'!$C$28,IF([1]Inputs_Outputs!$B$5="Paper",(LCA!$E$30*'[1]LOCH Calc COE Calc'!$C$28),IF([1]Inputs_Outputs!$B$5="Forest",LCA!$E$31*'[1]LOCH Calc COE Calc'!$C$28))))) -> 74440334 | R32: =IF(M32="","",$E$2*1000*'[1]LOCH Calc COE Calc'!$C$44) -> 4896457.3 | S32: =IF(N32="","",SUM(O32:R32)/('[1]LOCH Calc COE Calc'!$C$28)) -> 67.432371 | T32: =IF(L32="","",O32/'[1]LOCH Calc COE Calc'!$C$28) -> 63.802488 | U32: =IF(L32="","",P32/'[1]LOCH Calc COE Calc'!$C$28) -> 0.20873882 | V32: =IF(L32="","",Q32/'[1]LOCH Calc COE Calc'!$C$28) -> 3.21 | W32: =IF(L32="","",R32/'[1]LOCH Calc COE Calc'!$C$28) -> 0.21114397
L33: =IF('[1]All Data '!BE38="","",'[1]All Data '!BE38) -> 0.055 | M33: =IF('[1]All Data '!BF38="","",'[1]All Data '!BF38) -> 4767.5628 | N33: =IF('[1]All Data '!BB38="","",'[1]All Data '!BC38/'[1]All Data '!BH38) -> 306685.4 | O33: =IF(N33="","",M33*N33) -> 1.4621419e+09 | P33: =IF(M33="","",$C$2*(1-L33)*907.2/0.621371*N33*[1]Transportation!$M$40) -> 4783603 | Q33: =IF(L33="","",IF([1]Inputs_Outputs!$B$5="Herbaceous",(LCA!$E$29*'[1]LOCH Calc COE Calc'!$C$28),IF([1]Inputs_Outputs!$B$5="Woody",$E$28*'[1]LOCH Calc COE Calc'!$C$28,IF([1]Inputs_Outputs!$B$5="Paper",(LCA!$E$30*'[1]LOCH Calc COE Calc'!$C$28),IF([1]Inputs_Outputs!$B$5="Forest",LCA!$E$31*'[1]LOCH Calc COE Calc'!$C$28))))) -> 74440334 | R33: =IF(M33="","",$E$2*1000*'[1]LOCH Calc COE Calc'!$C$44) -> 4896457.3 | S33: =IF(N33="","",SUM(O33:R33)/('[1]LOCH Calc COE Calc'!$C$28)) -> 66.677588 | T33: =IF(L33="","",O33/'[1]LOCH Calc COE Calc'!$C$28) -> 63.050167 | U33: =IF(L33="","",P33/'[1]LOCH Calc COE Calc'!$C$28) -> 0.20627749 | V33: =IF(L33="","",Q33/'[1]LOCH Calc COE Calc'!$C$28) -> 3.21 | W33: =IF(L33="","",R33/'[1]LOCH Calc COE Calc'!$C$28) -> 0.21114397
L34: =IF('[1]All Data '!BE39="","",'[1]All Data '!BE39) -> 0.055 | M34: =IF('[1]All Data '!BF39="","",'[1]All Data '!BF39) -> 4767.5628 | N34: =IF('[1]All Data '!BB39="","",'[1]All Data '!BC39/'[1]All Data '!BH39) -> 304110.8 | O34: =IF(N34="","",M34*N34) -> 1.4498673e+09 | P34: =IF(M34="","",$C$2*(1-L34)*907.2/0.621371*N34*[1]Transportation!$M$40) -> 4743445 | Q34: =IF(L34="","",IF([1]Inputs_Outputs!$B$5="Herbaceous",(LCA!$E$29*'[1]LOCH Calc COE Calc'!$C$28),IF([1]Inputs_Outputs!$B$5="Woody",$E$28*'[1]LOCH Calc COE Calc'!$C$28,IF([1]Inputs_Outputs!$B$5="Paper",(LCA!$E$30*'[1]LOCH Calc COE Calc'!$C$28),IF([1]Inputs_Outputs!$B$5="Forest",LCA!$E$31*'[1]LOCH Calc COE Calc'!$C$28))))) -> 74440334 | R34: =IF(M34="","",$E$2*1000*'[1]LOCH Calc COE Calc'!$C$44) -> 4896457.3 | S34: =IF(N34="","",SUM(O34:R34)/('[1]LOCH Calc COE Calc'!$C$28)) -> 66.146556 | T34: =IF(L34="","",O34/'[1]LOCH Calc COE Calc'!$C$28) -> 62.520866 | U34: =IF(L34="","",P34/'[1]LOCH Calc COE Calc'!$C$28) -> 0.20454581 | V34: =IF(L34="","",Q34/'[1]LOCH Calc COE Calc'!$C$28) -> 3.21 | W34: =IF(L34="","",R34/'[1]LOCH Calc COE Calc'!$C$28) -> 0.21114397
L35: =IF('[1]All Data '!BE40="","",'[1]All Data '!BE40) -> 0.055 | M35: =IF('[1]All Data '!BF40="","",'[1]All Data '!BF40) -> 4767.5628 | N35: =IF('[1]All Data '!BB40="","",'[1]All Data '!BC40/'[1]All Data '!BH40) -> 303454.4 | O35: =IF(N35="","",M35*N35) -> 1.4467379e+09 | P35: =IF(M35="","",$C$2*(1-L35)*907.2/0.621371*N35*[1]Transportation!$M$40) -> 4733206.7 | Q35: =IF(L35="","",IF([1]Inputs_Outputs!$B$5="Herbaceous",(LCA!$E$29*'[1]LOCH Calc COE Calc'!$C$28),IF([1]Inputs_Outputs!$B$5="Woody",$E$28*'[1]LOCH Calc COE Calc'!$C$28,IF([1]Inputs_Outputs!$B$5="Paper",(LCA!$E$30*'[1]LOCH Calc COE Calc'!$C$28),IF([1]Inputs_Outputs!$B$5="Forest",LCA!$E$31*'[1]LOCH Calc COE Calc'!$C$28))))) -> 74440334 | R35: =IF(M35="","",$E$2*1000*'[1]LOCH Calc COE Calc'!$C$44) -> 4896457.3 | S35: =IF(N35="","",SUM(O35:R35)/('[1]LOCH Calc COE Calc'!$C$28)) -> 66.011168 | T35: =IF(L35="","",O35/'[1]LOCH Calc COE Calc'!$C$28) -> 62.385919 | U35: =IF(L35="","",P35/'[1]LOCH Calc COE Calc'!$C$28) -> 0.20410431 | V35: =IF(L35="","",Q35/'[1]LOCH Calc COE Calc'!$C$28) -> 3.21 | W35: =IF(L35="","",R35/'[1]LOCH Calc COE Calc'!$C$28) -> 0.21114397
L36: =IF('[1]All Data '!BE41="","",'[1]All Data '!BE41) -> 0.055 | M36: =IF('[1]All Data '!BF41="","",'[1]All Data '!BF41) -> 4767.5628 | N36: =IF('[1]All Data '!BB41="","",'[1]All Data '!BC41/'[1]All Data '!BH41) -> 303270.6 | O36: =IF(N36="","",M36*N36) -> 1.4458616e+09 | P36: =IF(M36="","",$C$2*(1-L36)*907.2/0.621371*N36*[1]Transportation!$M$40) -> 4730339.8 | Q36: =IF(L36="","",IF([1]Inputs_Outputs!$B$5="Herbaceous",(LCA!$E$29*'[1]LOCH Calc COE Calc'!$C$28),IF([1]Inputs_Outputs!$B$5="Woody",$E$28*'[1]LOCH Calc COE Calc'!$C$28,IF([1]Inputs_Outputs!$B$5="Paper",(LCA!$E$30*'[1]LOCH Calc COE Calc'!$C$28),IF([1]Inputs_Outputs!$B$5="Forest",LCA!$E$31*'[1]LOCH Calc COE Calc'!$C$28))))) -> 74440334 | R36: =IF(M36="","",$E$2*1000*'[1]LOCH Calc COE Calc'!$C$44) -> 4896457.3 | S36: =IF(N36="","",SUM(O36:R36)/('[1]LOCH Calc COE Calc'!$C$28)) -> 65.973257 | T36: =IF(L36="","",O36/'[1]LOCH Calc COE Calc'!$C$28) -> 62.348133 | U36: =IF(L36="","",P36/'[1]LOCH Calc COE Calc'!$C$28) -> 0.20398069 | V36: =IF(L36="","",Q36/'[1]LOCH Calc COE Calc'!$C$28) -> 3.21 | W36: =IF(L36="","",R36/'[1]LOCH Calc COE Calc'!$C$28) -> 0.21114397
L37: =IF('[1]All Data '!BE42="","",'[1]All Data '!BE42) -> 0.055 | M37: =IF('[1]All Data '!BF42="","",'[1]All Data '!BF42) -> 4767.5628 | N37: =IF('[1]All Data '!BB42="","",'[1]All Data '!BC42/'[1]All Data '!BH42) -> 302425.6 | O37: =IF(N37="","",M37*N37) -> 1.441833e+09 | P37: =IF(M37="","",$C$2*(1-L37)*907.2/0.621371*N37*[1]Transportation!$M$40) -> 4717159.7 | Q37: =IF(L37="","",IF([1]Inputs_Outputs!$B$5="Herbaceous",(LCA!$E$29*'[1]LOCH Calc COE Calc'!$C$28),IF([1]Inputs_Outputs!$B$5="Woody",$E$28*'[1]LOCH Calc COE Calc'!$C$28,IF([1]Inputs_Outputs!$B$5="Paper",(LCA!$E$30*'[1]LOCH Calc COE Calc'!$C$28),IF([1]Inputs_Outputs!$B$5="Forest",LCA!$E$31*'[1]LOCH Calc COE Calc'!$C$28))))) -> 74440334 | R37: =IF(M37="","",$E$2*1000*'[1]LOCH Calc COE Calc'!$C$44) -> 4896457.3 | S37: =IF(N37="","",SUM(O37:R37)/('[1]LOCH Calc COE Calc'!$C$28)) -> 65.798969 | T37: =IF(L37="","",O37/'[1]LOCH Calc COE Calc'!$C$28) -> 62.174413 | U37: =IF(L37="","",P37/'[1]LOCH Calc COE Calc'!$C$28) -> 0.20341234 | V37: =IF(L37="","",Q37/'[1]LOCH Calc COE Calc'!$C$28) -> 3.21 | W37: =IF(L37="","",R37/'[1]LOCH Calc COE Calc'!$C$28) -> 0.21114397
L38: =IF('[1]All Data '!BE43="","",'[1]All Data '!BE43) -> 0.055 | M38: =IF('[1]All Data '!BF43="","",'[1]All Data '!BF43) -> 4767.5628 | N38: =IF('[1]All Data '!BB43="","",'[1]All Data '!BC43/'[1]All Data '!BH43) -> 301184.4 | O38: =IF(N38="","",M38*N38) -> 1.4359155e+09 | P38: =IF(M38="","",$C$2*(1-L38)*907.2/0.621371*N38*[1]Transportation!$M$40) -> 4697799.8 | Q38: =IF(L38="","",IF([1]Inputs_Outputs!$B$5="Herbaceous",(LCA!$E$29*'[1]LOCH Calc COE Calc'!$C$28),IF([1]Inputs_Outputs!$B$5="Woody",$E$28*'[1]LOCH Calc COE Calc'!$C$28,IF([1]Inputs_Outputs!$B$5="Paper",(LCA!$E$30*'[1]LOCH Calc COE Calc'!$C$28),IF([1]Inputs_Outputs!$B$5="Forest",LCA!$E$31*'[1]LOCH Calc COE Calc'!$C$28))))) -> 74440334 | R38: =IF(M38="","",$E$2*1000*'[1]LOCH Calc COE Calc'!$C$44) -> 4896457.3 | S38: =IF(N38="","",SUM(O38:R38)/('[1]LOCH Calc COE Calc'!$C$28)) -> 65.542961 | T38: =IF(L38="","",O38/'[1]LOCH Calc COE Calc'!$C$28) -> 61.919239 | U38: =IF(L38="","",P38/'[1]LOCH Calc COE Calc'!$C$28) -> 0.20257751 | V38: =IF(L38="","",Q38/'[1]LOCH Calc COE Calc'!$C$28) -> 3.21 | W38: =IF(L38="","",R38/'[1]LOCH Calc COE Calc'!$C$28) -> 0.21114397
L39: =IF('[1]All Data '!BE44="","",'[1]All Data '!BE44) -> 0.055 | M39: =IF('[1]All Data '!BF44="","",'[1]All Data '!BF44) -> 4767.5628 | N39: =IF('[1]All Data '!BB44="","",'[1]All Data '!BC44/'[1]All Data '!BH44) -> 300348.8 | O39: =IF(N39="","",M39*N39) -> 1.4319318e+09 | P39: =IF(M39="","",$C$2*(1-L39)*907.2/0.621371*N39*[1]Transportation!$M$40) -> 4684766.3 | Q39: =IF(L39="","",IF([1]Inputs_Outputs!$B$5="Herbaceous",(LCA!$E$29*'[1]LOCH Calc COE Calc'!$C$28),IF([1]Inputs_Outputs!$B$5="Woody",$E$28*'[1]LOCH Calc COE Calc'!$C$28,IF([1]Inputs_Outputs!$B$5="Paper",(LCA!$E$30*'[1]LOCH Calc COE Calc'!$C$28),IF([1]Inputs_Outputs!$B$5="Forest",LCA!$E$31*'[1]LOCH Calc COE Calc'!$C$28))))) -> 74440334 | R39: =IF(M39="","",$E$2*1000*'[1]LOCH Calc COE Calc'!$C$44) -> 4896457.3 | S39: =IF(N39="","",SUM(O39:R39)/('[1]LOCH Calc COE Calc'!$C$28)) -> 65.370611 | T39: =IF(L39="","",O39/'[1]LOCH Calc COE Calc'!$C$28) -> 61.747452 | U39: =IF(L39="","",P39/'[1]LOCH Calc COE Calc'!$C$28) -> 0.20201548 | V39: =IF(L39="","",Q39/'[1]LOCH Calc COE Calc'!$C$28) -> 3.21 | W39: =IF(L39="","",R39/'[1]LOCH Calc COE Calc'!$C$28) -> 0.21114397
L40: =IF('[1]All Data '!BE45="","",'[1]All Data '!BE45) -> 0.055 | M40: =IF('[1]All Data '!BF45="","",'[1]All Data '!BF45) -> 4767.5628 | N40: =IF('[1]All Data '!BB45="","",'[1]All Data '!BC45/'[1]All Data '!BH45) -> 299836 | O40: =IF(N40="","",M40*N40) -> 1.429487e+09 | P40: =IF(M40="","",$C$2*(1-L40)*907.2/0.621371*N40*[1]Transportation!$M$40) -> 4676767.8 | Q40: =IF(L40="","",IF([1]Inputs_Outputs!$B$5="Herbaceous",(LCA!$E$29*'[1]LOCH Calc COE Calc'!$C$28),IF([1]Inputs_Outputs!$B$5="Woody",$E$28*'[1]LOCH Calc COE Calc'!$C$28,IF([1]Inputs_Outputs!$B$5="Paper",(LCA!$E$30*'[1]LOCH Calc COE Calc'!$C$28),IF([1]Inputs_Outputs!$B$5="Forest",LCA!$E$31*'[1]LOCH Calc COE Calc'!$C$28))))) -> 74440334 | R40: =IF(M40="","",$E$2*1000*'[1]LOCH Calc COE Calc'!$C$44) -> 4896457.3 | S40: =IF(N40="","",SUM(O40:R40)/('[1]LOCH Calc COE Calc'!$C$28)) -> 65.264842 | T40: =IF(L40="","",O40/'[1]LOCH Calc COE Calc'!$C$28) -> 61.642028 | U40: =IF(L40="","",P40/'[1]LOCH Calc COE Calc'!$C$28) -> 0.20167057 | V40: =IF(L40="","",Q40/'[1]LOCH Calc COE Calc'!$C$28) -> 3.21 | W40: =IF(L40="","",R40/'[1]LOCH Calc COE Calc'!$C$28) -> 0.21114397
...
