Workbook
Name AboveSeal_Depth: '[4]Geo-Activity Interaction'!$E$35
Name AboveSeal_Depth_Units: '[4]Geo-Activity Interaction'!$F$35
Name AGRType: [5]InputsAndConstants!$G$8
Name AuxLoadTot: [6]Performance!$F$19
Name BioFeedAR: [5]EQDesignParameters!$C$7
Name booster_count: '[7]User Interface'!$G$10
Name Capture: [5]InputsAndConstants!$G$12
Name CarbonReplacement: [5]EQDesignParameters!$C$237
Name CarbonVolume: [5]EQDesignParameters!$C$238
Name Case_Number: '[5]Model Interface'!$A$17
Name co2_density: '[7]User Interface'!$G$9
Name co2_flow_rate: '[7]User Interface'!$C$7
Name CO2Emissions: [5]Emissions!$F$11
Name CO2TSpertonne: 'LOCH Calc COE Calc'!$B$11
Name CO2TSpertonne: #REF!
Name CoalFeedAR: [5]EQDesignParameters!$C$6
Name CoalPrice: 'LOCH Calc COE Calc'!$B$6
Name CoalPrice: '[8]COE Calc'!$O$6
Name CondDuty: [5]EQDesignParameters!$C$106
Name COSBedLife: [5]EQDesignParameters!$C$169
Name COSInitialFill: [5]EQDesignParameters!$C$168
Name CWFlow: [6]EQDesignParameters!$C$53
Name CWFlowVol: [6]EQDesignParameters!$C$54
Name CWRange: [6]EQDesignParameters!$C$51
Name d360.: '[4]Geol Sal'!$D$98
Name Dedicated: '[9]state coordinates'!#REF!
Name Drow: [10]InputsAndConstants!$C$12
Name Engineer_Rate: [4]Activity_Inputs!$E$10
Name Engineer_Rate_Units: [4]Activity_Inputs!$F$10
Name Field_Rate: [4]Activity_Inputs!$E$12
Name Field_Rate_Units: [4]Activity_Inputs!$F$12
Name Frow: [10]InputsAndConstants!$C$7
Name Geologist_Rate: [4]Activity_Inputs!$E$9
Name Geologist_Rate_Units: [4]Activity_Inputs!$F$9
Name graphic: INDIRECT('[9]Input Output Interface'!$C$10)
Name GrossPower: [6]Performance!$F$7
Name Groundwater_Depth: '[4]Geo-Activity Interaction'!$E$36
Name Groundwater_Depth_Units: '[4]Geo-Activity Interaction'!$F$36
Name HClNaOHFlow: [5]EQDesignParameters!$C$374
Name HgEmissions: [5]InputsAndConstants!$C$63
Name hp2kW: [5]InputsAndConstants!$G$56
Name HRSGDuty: [6]EQDesignParameters!$C$25
Name infrastructure: '[9]Input Output Interface'!$C$10
Name Injection_Depth: '[4]Geo-Activity Interaction'!$E$32
Name Injection_Depth_Units: '[4]Geo-Activity Interaction'!$F$32
Name InReservoir_Depth: '[4]Geo-Activity Interaction'!$E$34
Name InReservoir_Depth_Units: '[4]Geo-Activity Interaction'!$F$34
Name IQ_CH: 110000
Name IQ_CQ: 5000
Name IQ_CY: 10000
Name IQ_DAILY: 500000
Name IQ_FH: 100000
Name IQ_FQ: 500
Name IQ_FY: 1000
Name IQ_LTM: 2000
Name IQ_MONTH: 15000
Name IQ_NTM: 6000
Name IQ_WEEK: 50000
Name IQ_YTD: 3000
Name L_PL: '[11]Eng Mod'!$D$16

Sheet LOCH Calc COE Calc
A1: LCOH (Real) Calculation | R1: Biomass Cost | S1: MC | T1: Dry tons needed | U1: Variable Fuel Cost | V1: Fuel $/kg Co2 | W1: Total LCOH (no T&S) | X1: CO2 T&S cost ($2023/tCO2) | Y1: CO2 T&S cost ($2022/kg H2) | Z1: Total LCOH
A2: Rev4 Fixed Charge Factors | B2: FCR | C2: TASC/TOC | D2: Financial Type | F2: LCOE Capital component = FCR * TASC/TOC * TOC | P2: =IF('[1]All Data '!AZ7="","",'[1]All Data '!AZ7) -> Steele County | Q2: =IF('[1]All Data '!BB7="","",'[1]All Data '!BB7) -> MN | R2: =IF('[1]All Data '!BD7="","",'[1]All Data '!BD7) -> 70 | S2: =IF(R2="","",'[1]All Data '!BE7) -> 0.2 | T2: =IF(S2="","",[1]Inputs_Outputs!$B$8*(1-'LOCH Calc COE Calc'!S2)) -> 254466.23 | U2: =IF(S2="","",R2*T2*365*$B$19/100) -> 52012898 | V2: =IF(S2="","",(U2*$B$19)/(($B$28)*$B$19)) -> 1.7943111 | W2: =IF(S2="","",V2+$C$49+$C$50+$C$51) -> 6.6227146 | X2: =IF(W2="","",LOOKUP(_xlfn.CONCAT(P2,", ",Q2),'[1]T+S Costs'!$F$2:$F$3138,'[1]T+S Costs'!$N$2:$N$3138)) -> 27.432117 | Y2: =IF(X2="","",((X2*$B$60/$B$59)*$C$44)/$C$28) -> 0.55115077 | Z2: =IF(Y2="","",W2+Y2) -> 7.1738654
A3: IOU 3-year Fixed Charge Rate (NGCC/NG Reforming) | B3: =RealFCR -> 0.058571541 | C3: =RealTASC_3yr -> 1.0698019 | D3: (33-yr IOU) | F3: FCR's and TASC/TOC factors are from Rev3 (September 2019 version) of the Cost Estimating Methodology QGESS; they assume plant startup in 2023, and values are in the real dollar years of TOC and O&M (i.e. 2018$). | P3: =IF('[1]All Data '!AZ8="","",'[1]All Data '!AZ8) -> Carroll County | Q3: =IF('[1]All Data '!BB8="","",'[1]All Data '!BB8) -> IN | R3: =IF('[1]All Data '!BD8="","",'[1]All Data '!BD8) -> 70 | S3: =IF(R3="","",'[1]All Data '!BE8) -> 0.2 | T3: =IF(S3="","",[1]Inputs_Outputs!$B$8*(1-'LOCH Calc COE Calc'!S3)) -> 254466.23 | U3: =IF(S3="","",R3*T3*365*$B$19/100) -> 52012898 | V3: =IF(S3="","",(U3*$B$19)/(($B$28)*$B$19)) -> 1.7943111 | W3: =IF(S3="","",V3+$C$49+$C$50+$C$51) -> 6.6227146 | X3: =IF(W3="","",LOOKUP(_xlfn.CONCAT(P3,", ",Q3),'[1]T+S Costs'!$F$2:$F$3138,'[1]T+S Costs'!$N$2:$N$3138)) -> 16.367856 | Y3: =IF(X3="","",((X3*$B$60/$B$59)*$C$44)/$C$28) -> 0.32885383 | Z3: =IF(Y3="","",W3+Y3) -> 6.9515684
A4: IOU 5-year Fixed Charge Rate (PC/IGCC/Coal Gasification) | B4: =RealFCR -> 0.058571541 | C4: =RealTASC_5yr -> 1.1163365 | D4: (35-yr IOU) | P4: =IF('[1]All Data '!AZ9="","",'[1]All Data '!AZ9) -> McLean County | Q4: =IF('[1]All Data '!BB9="","",'[1]All Data '!BB9) -> IL | R4: =IF('[1]All Data '!BD9="","",'[1]All Data '!BD9) -> 70 | S4: =IF(R4="","",'[1]All Data '!BE9) -> 0.2 | T4: =IF(S4="","",[1]Inputs_Outputs!$B$8*(1-'LOCH Calc COE Calc'!S4)) -> 254466.23 | U4: =IF(S4="","",R4*T4*365*$B$19/100) -> 52012898 | V4: =IF(S4="","",(U4*$B$19)/(($B$28)*$B$19)) -> 1.7943111 | W4: =IF(S4="","",V4+$C$49+$C$50+$C$51) -> 6.6227146 | X4: =IF(W4="","",LOOKUP(_xlfn.CONCAT(P4,", ",Q4),'[1]T+S Costs'!$F$2:$F$3138,'[1]T+S Costs'!$N$2:$N$3138)) -> 9.6567204 | Y4: =IF(X4="","",((X4*$B$60/$B$59)*$C$44)/$C$28) -> 0.19401744 | Z4: =IF(Y4="","",W4+Y4) -> 6.816732
A5: Rev4 Fuel Costs (2018 cost in 2018 dollars) | P5: =IF('[1]All Data '!AZ10="","",'[1]All Data '!AZ10) -> Putnam County | Q5: =IF('[1]All Data '!BB10="","",'[1]All Data '!BB10) -> IL | R5: =IF('[1]All Data '!BD10="","",'[1]All Data '!BD10) -> 70 | S5: =IF(R5="","",'[1]All Data '!BE10) -> 0.2 | T5: =IF(S5="","",[1]Inputs_Outputs!$B$8*(1-'LOCH Calc COE Calc'!S5)) -> 254466.23 | U5: =IF(S5="","",R5*T5*365*$B$19/100) -> 52012898 | V5: =IF(S5="","",(U5*$B$19)/(($B$28)*$B$19)) -> 1.7943111 | W5: =IF(S5="","",V5+$C$49+$C$50+$C$51) -> 6.6227146 | X5: =IF(W5="","",LOOKUP(_xlfn.CONCAT(P5,", ",Q5),'[1]T+S Costs'!$F$2:$F$3138,'[1]T+S Costs'!$N$2:$N$3138)) -> 11.442911 | Y5: =IF(X5="","",((X5*$B$60/$B$59)*$C$44)/$C$28) -> 0.22990458 | Z5: =IF(Y5="","",W5+Y5) -> 6.8526192
A6: Illinois No. 6 Coal Delivered to Midwest | B6: 2.2269 | C6: $/MMBtu | D6: =CoalPrice/1000000*11666*2000 -> 51.958031 | E6: $/ton | F6: These fuel prices are from the January 2019 version update of the Fuel Pricing QGESS provided by Gavin Pickenpaugh. They will be referred to as only 2018$ fuel costs. | P6: =IF('[1]All Data '!AZ11="","",'[1]All Data '!AZ11) -> Sibley County | Q6: =IF('[1]All Data '!BB11="","",'[1]All Data '!BB11) -> MN | R6: =IF('[1]All Data '!BD11="","",'[1]All Data '!BD11) -> 70 | S6: =IF(R6="","",'[1]All Data '!BE11) -> 0.19985396 | T6: =IF(S6="","",[1]Inputs_Outputs!$B$8*(1-'LOCH Calc COE Calc'!S6)) -> 254512.68 | U6: =IF(S6="","",R6*T6*365*$B$19/100) -> 52022393 | V6: =IF(S6="","",(U6*$B$19)/(($B$28)*$B$19)) -> 1.7946387 | W6: =IF(S6="","",V6+$C$49+$C$50+$C$51) -> 6.6230422 | X6: =IF(W6="","",LOOKUP(_xlfn.CONCAT(P6,", ",Q6),'[1]T+S Costs'!$F$2:$F$3138,'[1]T+S Costs'!$N$2:$N$3138)) -> 19.456568 | Y6: =IF(X6="","",((X6*$B$60/$B$59)*$C$44)/$C$28) -> 0.3909105 | Z6: =IF(Y6="","",W6+Y6) -> 7.0139527
A7: Natural Gas Delivered to Midwest | B7: 4.4202 | C7: $/MMBtu | P7: =IF('[1]All Data '!AZ12="","",'[1]All Data '!AZ12) -> Livingston County | Q7: =IF('[1]All Data '!BB12="","",'[1]All Data '!BB12) -> IL | R7: =IF('[1]All Data '!BD12="","",'[1]All Data '!BD12) -> 70 | S7: =IF(R7="","",'[1]All Data '!BE12) -> 0.2 | T7: =IF(S7="","",[1]Inputs_Outputs!$B$8*(1-'LOCH Calc COE Calc'!S7)) -> 254466.23 | U7: =IF(S7="","",R7*T7*365*$B$19/100) -> 52012898 | V7: =IF(S7="","",(U7*$B$19)/(($B$28)*$B$19)) -> 1.7943111 | W7: =IF(S7="","",V7+$C$49+$C$50+$C$51) -> 6.6227146 | X7: =IF(W7="","",LOOKUP(_xlfn.CONCAT(P7,", ",Q7),'[1]T+S Costs'!$F$2:$F$3138,'[1]T+S Costs'!$N$2:$N$3138)) -> 10.778282 | Y7: =IF(X7="","",((X7*$B$60/$B$59)*$C$44)/$C$28) -> 0.21655122 | Z7: =IF(Y7="","",W7+Y7) -> 6.8392658
A8: Woody Biomass (Torrefied) Delivered to East Texas | B8: =D8*1000000/9749/2000 -> 7.9073562 | C8: $/MMBtu | D8: 154.17763 | E8: $/ton | F8: This price is a calculated levelized price based on the reference price of delivered SYP (torrefied) provided in the report "Comprehensive Analysis of Coal and Biomass Conversion to Jet Fuel: Oxygen Blown, Transport Reactor Integrated Gasifier (TRIG) and Fischer-Tropsch (F-T) Catalyst Configurations," NETL, 2014. The price has been escalated from 2007$ to 2018$ | P8: =IF('[1]All Data '!AZ13="","",'[1]All Data '!AZ13) -> Kane County | Q8: =IF('[1]All Data '!BB13="","",'[1]All Data '!BB13) -> IL | R8: =IF('[1]All Data '!BD13="","",'[1]All Data '!BD13) -> 70 | S8: =IF(R8="","",'[1]All Data '!BE13) -> 0.2 | T8: =IF(S8="","",[1]Inputs_Outputs!$B$8*(1-'LOCH Calc COE Calc'!S8)) -> 254466.23 | U8: =IF(S8="","",R8*T8*365*$B$19/100) -> 52012898 | V8: =IF(S8="","",(U8*$B$19)/(($B$28)*$B$19)) -> 1.7943111 | W8: =IF(S8="","",V8+$C$49+$C$50+$C$51) -> 6.6227146 | X8: =IF(W8="","",LOOKUP(_xlfn.CONCAT(P8,", ",Q8),'[1]T+S Costs'!$F$2:$F$3138,'[1]T+S Costs'!$N$2:$N$3138)) -> 14.779903 | Y8: =IF(X8="","",((X8*$B$60/$B$59)*$C$44)/$C$28) -> 0.29694955 | Z8: =IF(Y8="","",W8+Y8) -> 6.9196642
A9: Woody Biomass (Raw) | B9: 2.7515655 | C9: $/MMBtu | D9: 27.08711 | E9: $/ton | P9: =IF('[1]All Data '!AZ14="","",'[1]All Data '!AZ14) -> De Kalb County | Q9: =IF('[1]All Data '!BB14="","",'[1]All Data '!BB14) -> IL | R9: =IF('[1]All Data '!BD14="","",'[1]All Data '!BD14) -> 70 | S9: =IF(R9="","",'[1]All Data '!BE14) -> 0.2 | T9: =IF(S9="","",[1]Inputs_Outputs!$B$8*(1-'LOCH Calc COE Calc'!S9)) -> 254466.23 | U9: =IF(S9="","",R9*T9*365*$B$19/100) -> 52012898 | V9: =IF(S9="","",(U9*$B$19)/(($B$28)*$B$19)) -> 1.7943111 | W9: =IF(S9="","",V9+$C$49+$C$50+$C$51) -> 6.6227146 | X9: =IF(W9="","",LOOKUP(_xlfn.CONCAT(P9,", ",Q9),'[1]T+S Costs'!$F$2:$F$3138,'[1]T+S Costs'!$N$2:$N$3138)) -> 14.51682 | Y9: =IF(X9="","",((X9*$B$60/$B$59)*$C$44)/$C$28) -> 0.29166385 | Z9: =IF(Y9="","",W9+Y9) -> 6.9143785
A10: Rev4 Other Costs (2018 cost in 2018 dollars) | P10: =IF('[1]All Data '!AZ15="","",'[1]All Data '!AZ15) -> Waseca County | Q10: =IF('[1]All Data '!BB15="","",'[1]All Data '!BB15) -> MN | R10: =IF('[1]All Data '!BD15="","",'[1]All Data '!BD15) -> 70 | S10: =IF(R10="","",'[1]All Data '!BE15) -> 0.2 | T10: =IF(S10="","",[1]Inputs_Outputs!$B$8*(1-'LOCH Calc COE Calc'!S10)) -> 254466.23 | U10: =IF(S10="","",R10*T10*365*$B$19/100) -> 52012898 | V10: =IF(S10="","",(U10*$B$19)/(($B$28)*$B$19)) -> 1.7943111 | W10: =IF(S10="","",V10+$C$49+$C$50+$C$51) -> 6.6227146 | X10: =IF(W10="","",LOOKUP(_xlfn.CONCAT(P10,", ",Q10),'[1]T+S Costs'!$F$2:$F$3138,'[1]T+S Costs'!$N$2:$N$3138)) -> 19.456568 | Y10: =IF(X10="","",((X10*$B$60/$B$59)*$C$44)/$C$28) -> 0.3909105 | Z10: =IF(Y10="","",W10+Y10) -> 7.0136251
A11: CO₂ T&S in Texas to East Texas Basin | B11: 21.65 | C11: $/tonne CO₂ | F11: T&S cost is from the August 2019 update to the T&S QGESS, using the final LCOE Financial Parameters/Methodology, and reported in 2018$. | P11: =IF('[1]All Data '!AZ16="","",'[1]All Data '!AZ16) -> Chippewa County | Q11: =IF('[1]All Data '!BB16="","",'[1]All Data '!BB16) -> MN | R11: =IF('[1]All Data '!BD16="","",'[1]All Data '!BD16) -> 70 | S11: =IF(R11="","",'[1]All Data '!BE16) -> 0.2 | T11: =IF(S11="","",[1]Inputs_Outputs!$B$8*(1-'LOCH Calc COE Calc'!S11)) -> 254466.23 | U11: =IF(S11="","",R11*T11*365*$B$19/100) -> 52012898 | V11: =IF(S11="","",(U11*$B$19)/(($B$28)*$B$19)) -> 1.7943111 | W11: =IF(S11="","",V11+$C$49+$C$50+$C$51) -> 6.6227146 | X11: =IF(W11="","",LOOKUP(_xlfn.CONCAT(P11,", ",Q11),'[1]T+S Costs'!$F$2:$F$3138,'[1]T+S Costs'!$N$2:$N$3138)) -> 25.119761 | Y11: =IF(X11="","",((X11*$B$60/$B$59)*$C$44)/$C$28) -> 0.50469222 | Z11: =IF(Y11="","",W11+Y11) -> 7.1274068
A12: Grid Electricity US Average | B12: 69.2 | C12: $/MWh | P12: =IF('[1]All Data '!AZ17="","",'[1]All Data '!AZ17) -> Swift County | Q12: =IF('[1]All Data '!BB17="","",'[1]All Data '!BB17) -> MN | R12: =IF('[1]All Data '!BD17="","",'[1]All Data '!BD17) -> 70 | S12: =IF(R12="","",'[1]All Data '!BE17) -> 0.2 | T12: =IF(S12="","",[1]Inputs_Outputs!$B$8*(1-'LOCH Calc COE Calc'!S12)) -> 254466.23 | U12: =IF(S12="","",R12*T12*365*$B$19/100) -> 52012898 | V12: =IF(S12="","",(U12*$B$19)/(($B$28)*$B$19)) -> 1.7943111 | W12: =IF(S12="","",V12+$C$49+$C$50+$C$51) -> 6.6227146 | X12: =IF(W12="","",LOOKUP(_xlfn.CONCAT(P12,", ",Q12),'[1]T+S Costs'!$F$2:$F$3138,'[1]T+S Costs'!$N$2:$N$3138)) -> 25.355151 | Y12: =IF(X12="","",((X12*$B$60/$B$59)*$C$44)/$C$28) -> 0.50942153 | Z12: =IF(Y12="","",W12+Y12) -> 7.1321361
A13: Export Steam | B13: 0 | C13: $/ton | P13: =IF('[1]All Data '!AZ18="","",'[1]All Data '!AZ18) -> Blue Earth County | Q13: =IF('[1]All Data '!BB18="","",'[1]All Data '!BB18) -> MN | R13: =IF('[1]All Data '!BD18="","",'[1]All Data '!BD18) -> 70 | S13: =IF(R13="","",'[1]All Data '!BE18) -> 0.2 | T13: =IF(S13="","",[1]Inputs_Outputs!$B$8*(1-'LOCH Calc COE Calc'!S13)) -> 254466.23 | U13: =IF(S13="","",R13*T13*365*$B$19/100) -> 52012898 | V13: =IF(S13="","",(U13*$B$19)/(($B$28)*$B$19)) -> 1.7943111 | W13: =IF(S13="","",V13+$C$49+$C$50+$C$51) -> 6.6227146 | X13: =IF(W13="","",LOOKUP(_xlfn.CONCAT(P13,", ",Q13),'[1]T+S Costs'!$F$2:$F$3138,'[1]T+S Costs'!$N$2:$N$3138)) -> 25.123193 | Y13: =IF(X13="","",((X13*$B$60/$B$59)*$C$44)/$C$28) -> 0.50476116 | Z13: =IF(Y13="","",W13+Y13) -> 7.1274758
P14: =IF('[1]All Data '!AZ19="","",'[1]All Data '!AZ19) -> Kossuth County | Q14: =IF('[1]All Data '!BB19="","",'[1]All Data '!BB19) -> IA | R14: =IF('[1]All Data '!BD19="","",'[1]All Data '!BD19) -> 70 | S14: =IF(R14="","",'[1]All Data '!BE19) -> 0.2 | T14: =IF(S14="","",[1]Inputs_Outputs!$B$8*(1-'LOCH Calc COE Calc'!S14)) -> 254466.23 | U14: =IF(S14="","",R14*T14*365*$B$19/100) -> 52012898 | V14: =IF(S14="","",(U14*$B$19)/(($B$28)*$B$19)) -> 1.7943111 | W14: =IF(S14="","",V14+$C$49+$C$50+$C$51) -> 6.6227146 | X14: =IF(W14="","",LOOKUP(_xlfn.CONCAT(P14,", ",Q14),'[1]T+S Costs'!$F$2:$F$3138,'[1]T+S Costs'!$N$2:$N$3138)) -> 24.140095 | Y14: =IF(X14="","",((X14*$B$60/$B$59)*$C$44)/$C$28) -> 0.48500932 | Z14: =IF(Y14="","",W14+Y14) -> 7.1077239
P15: =IF('[1]All Data '!AZ20="","",'[1]All Data '!AZ20) -> Scott County | Q15: =IF('[1]All Data '!BB20="","",'[1]All Data '!BB20) -> IA | R15: =IF('[1]All Data '!BD20="","",'[1]All Data '!BD20) -> 70 | S15: =IF(R15="","",'[1]All Data '!BE20) -> 0.2 | T15: =IF(S15="","",[1]Inputs_Outputs!$B$8*(1-'LOCH Calc COE Calc'!S15)) -> 254466.23 | U15: =IF(S15="","",R15*T15*365*$B$19/100) -> 52012898 | V15: =IF(S15="","",(U15*$B$19)/(($B$28)*$B$19)) -> 1.7943111 | W15: =IF(S15="","",V15+$C$49+$C$50+$C$51) -> 6.6227146 | X15: =IF(W15="","",LOOKUP(_xlfn.CONCAT(P15,", ",Q15),'[1]T+S Costs'!$F$2:$F$3138,'[1]T+S Costs'!$N$2:$N$3138)) -> 14.51682 | Y15: =IF(X15="","",((X15*$B$60/$B$59)*$C$44)/$C$28) -> 0.29166385 | Z15: =IF(Y15="","",W15+Y15) -> 6.9143785
P16: =IF('[1]All Data '!AZ21="","",'[1]All Data '!AZ21) -> Warren County | Q16: =IF('[1]All Data '!BB21="","",'[1]All Data '!BB21) -> IN | R16: =IF('[1]All Data '!BD21="","",'[1]All Data '!BD21) -> 70 | S16: =IF(R16="","",'[1]All Data '!BE21) -> 0.2 | T16: =IF(S16="","",[1]Inputs_Outputs!$B$8*(1-'LOCH Calc COE Calc'!S16)) -> 254466.23 | U16: =IF(S16="","",R16*T16*365*$B$19/100) -> 52012898 | V16: =IF(S16="","",(U16*$B$19)/(($B$28)*$B$19)) -> 1.7943111 | W16: =IF(S16="","",V16+$C$49+$C$50+$C$51) -> 6.6227146 | X16: =IF(W16="","",LOOKUP(_xlfn.CONCAT(P16,", ",Q16),'[1]T+S Costs'!$F$2:$F$3138,'[1]T+S Costs'!$N$2:$N$3138)) -> 10.503821 | Y16: =IF(X16="","",((X16*$B$60/$B$59)*$C$44)/$C$28) -> 0.2110369 | Z16: =IF(Y16="","",W16+Y16) -> 6.8337515
A17: Case | B17: Biomass Gasification Net-Zero Scenario | P17: =IF('[1]All Data '!AZ22="","",'[1]All Data '!AZ22) -> Brown County | Q17: =IF('[1]All Data '!BB22="","",'[1]All Data '!BB22) -> MN | R17: =IF('[1]All Data '!BD22="","",'[1]All Data '!BD22) -> 70 | S17: =IF(R17="","",'[1]All Data '!BE22) -> 0.19993285 | T17: =IF(S17="","",[1]Inputs_Outputs!$B$8*(1-'LOCH Calc COE Calc'!S17)) -> 254487.59 | U17: =IF(S17="","",R17*T17*365*$B$19/100) -> 52017263 | V17: =IF(S17="","",(U17*$B$19)/(($B$28)*$B$19)) -> 1.7944617 | W17: =IF(S17="","",V17+$C$49+$C$50+$C$51) -> 6.6228652 | X17: =IF(W17="","",LOOKUP(_xlfn.CONCAT(P17,", ",Q17),'[1]T+S Costs'!$F$2:$F$3138,'[1]T+S Costs'!$N$2:$N$3138)) -> 28.487877 | Y17: =IF(X17="","",((X17*$B$60/$B$59)*$C$44)/$C$28) -> 0.57236252 | Z17: =IF(Y17="","",W17+Y17) -> 7.1952277
A18: Case Description | B18: Biomass Gasification Net-Zero Scenario | P18: =IF('[1]All Data '!AZ23="","",'[1]All Data '!AZ23) -> Watonwan County | Q18: =IF('[1]All Data '!BB23="","",'[1]All Data '!BB23) -> MN | R18: =IF('[1]All Data '!BD23="","",'[1]All Data '!BD23) -> 70 | S18: =IF(R18="","",'[1]All Data '!BE23) -> 0.19993285 | T18: =IF(S18="","",[1]Inputs_Outputs!$B$8*(1-'LOCH Calc COE Calc'!S18)) -> 254487.59 | U18: =IF(S18="","",R18*T18*365*$B$19/100) -> 52017263 | V18: =IF(S18="","",(U18*$B$19)/(($B$28)*$B$19)) -> 1.7944617 | W18: =IF(S18="","",V18+$C$49+$C$50+$C$51) -> 6.6228652 | X18: =IF(W18="","",LOOKUP(_xlfn.CONCAT(P18,", ",Q18),'[1]T+S Costs'!$F$2:$F$3138,'[1]T+S Costs'!$N$2:$N$3138)) -> 21.658152 | Y18: =IF(X18="","",((X18*$B$60/$B$59)*$C$44)/$C$28) -> 0.43514349 | Z18: =IF(Y18="","",W18+Y18) -> 7.0580087
A19: Capacity Factor (%) | B19: ='[1]Net-Zero O&M'!$H$4/100 -> 0.8 | P19: =IF('[1]All Data '!AZ24="","",'[1]All Data '!AZ24) -> Clinton County | Q19: =IF('[1]All Data '!BB24="","",'[1]All Data '!BB24) -> IA | R19: =IF('[1]All Data '!BD24="","",'[1]All Data '!BD24) -> 70 | S19: =IF(R19="","",'[1]All Data '!BE24) -> 0.2 | T19: =IF(S19="","",[1]Inputs_Outputs!$B$8*(1-'LOCH Calc COE Calc'!S19)) -> 254466.23 | U19: =IF(S19="","",R19*T19*365*$B$19/100) -> 52012898 | V19: =IF(S19="","",(U19*$B$19)/(($B$28)*$B$19)) -> 1.7943111 | W19: =IF(S19="","",V19+$C$49+$C$50+$C$51) -> 6.6227146 | X19: =IF(W19="","",LOOKUP(_xlfn.CONCAT(P19,", ",Q19),'[1]T+S Costs'!$F$2:$F$3138,'[1]T+S Costs'!$N$2:$N$3138)) -> 13.959728 | Y19: =IF(X19="","",((X19*$B$60/$B$59)*$C$44)/$C$28) -> 0.28047106 | Z19: =IF(Y19="","",W19+Y19) -> 6.9031857
A20: Total Over Night Cost, $/1,000 | B20: ='[1]Net-Zero Cap'!$T$22 -> 777329.58 | P20: =IF('[1]All Data '!AZ25="","",'[1]All Data '!AZ25) -> Dodge County | Q20: =IF('[1]All Data '!BB25="","",'[1]All Data '!BB25) -> MN | R20: =IF('[1]All Data '!BD25="","",'[1]All Data '!BD25) -> 70 | S20: =IF(R20="","",'[1]All Data '!BE25) -> 0.2 | T20: =IF(S20="","",[1]Inputs_Outputs!$B$8*(1-'LOCH Calc COE Calc'!S20)) -> 254466.23 | U20: =IF(S20="","",R20*T20*365*$B$19/100) -> 52012898 | V20: =IF(S20="","",(U20*$B$19)/(($B$28)*$B$19)) -> 1.7943111 | W20: =IF(S20="","",V20+$C$49+$C$50+$C$51) -> 6.6227146 | X20: =IF(W20="","",LOOKUP(_xlfn.CONCAT(P20,", ",Q20),'[1]T+S Costs'!$F$2:$F$3138,'[1]T+S Costs'!$N$2:$N$3138)) -> 24.140095 | Y20: =IF(X20="","",((X20*$B$60/$B$59)*$C$44)/$C$28) -> 0.48500932 | Z20: =IF(Y20="","",W20+Y20) -> 7.1077239
A21: Total Over Night Cost, $M | B21: =B20/1000 -> 777.32958 | C21: Tons per year | P21: =IF('[1]All Data '!AZ26="","",'[1]All Data '!AZ26) -> Fountain County | Q21: =IF('[1]All Data '!BB26="","",'[1]All Data '!BB26) -> IN | R21: =IF('[1]All Data '!BD26="","",'[1]All Data '!BD26) -> 70 | S21: =IF(R21="","",'[1]All Data '!BE26) -> 0.2 | T21: =IF(S21="","",[1]Inputs_Outputs!$B$8*(1-'LOCH Calc COE Calc'!S21)) -> 254466.23 | U21: =IF(S21="","",R21*T21*365*$B$19/100) -> 52012898 | V21: =IF(S21="","",(U21*$B$19)/(($B$28)*$B$19)) -> 1.7943111 | W21: =IF(S21="","",V21+$C$49+$C$50+$C$51) -> 6.6227146 | X21: =IF(W21="","",LOOKUP(_xlfn.CONCAT(P21,", ",Q21),'[1]T+S Costs'!$F$2:$F$3138,'[1]T+S Costs'!$N$2:$N$3138)) -> 10.226892 | Y21: =IF(X21="","",((X21*$B$60/$B$59)*$C$44)/$C$28) -> 0.20547301 | Z21: =IF(Y21="","",W21+Y21) -> 6.8281876
A22: Fuel Consumption, TPD or MMBtu/day | B22: ='[1]Net-Zero O&M'!$D$53+'[1]Net-Zero O&M'!$D$54 -> 1000.0157 | C22: =B22*365*B19 -> 292004.58 | D22: =C22/C28*907 -> 11.420725 | P22: =IF('[1]All Data '!AZ27="","",'[1]All Data '!AZ27) -> Blackford County | Q22: =IF('[1]All Data '!BB27="","",'[1]All Data '!BB27) -> IN | R22: =IF('[1]All Data '!BD27="","",'[1]All Data '!BD27) -> 70 | S22: =IF(R22="","",'[1]All Data '!BE27) -> 0.2 | T22: =IF(S22="","",[1]Inputs_Outputs!$B$8*(1-'LOCH Calc COE Calc'!S22)) -> 254466.23 | U22: =IF(S22="","",R22*T22*365*$B$19/100) -> 52012898 | V22: =IF(S22="","",(U22*$B$19)/(($B$28)*$B$19)) -> 1.7943111 | W22: =IF(S22="","",V22+$C$49+$C$50+$C$51) -> 6.6227146 | X22: =IF(W22="","",LOOKUP(_xlfn.CONCAT(P22,", ",Q22),'[1]T+S Costs'!$F$2:$F$3138,'[1]T+S Costs'!$N$2:$N$3138)) -> 9.6453417 | Y22: =IF(X22="","",((X22*$B$60/$B$59)*$C$44)/$C$28) -> 0.19378882 | Z22: =IF(Y22="","",W22+Y22) -> 6.8165034
A23: First Year Fuel Cost, $ (100% CF) | B23: ='[1]Net-Zero O&M'!$G$55/B19 -> 56275718 | P23: =IF('[1]All Data '!AZ28="","",'[1]All Data '!AZ28) -> Richland County | Q23: =IF('[1]All Data '!BB28="","",'[1]All Data '!BB28) -> ND | R23: =IF('[1]All Data '!BD28="","",'[1]All Data '!BD28) -> 70 | S23: =IF(R23="","",'[1]All Data '!BE28) -> 0.18867628 | T23: =IF(S23="","",[1]Inputs_Outputs!$B$8*(1-'LOCH Calc COE Calc'!S23)) -> 258068.11 | U23: =IF(S23="","",R23*T23*365*$B$19/100) -> 52749122 | V23: =IF(S23="","",(U23*$B$19)/(($B$28)*$B$19)) -> 1.819709 | W23: =IF(S23="","",V23+$C$49+$C$50+$C$51) -> 6.6481124 | X23: =IF(W23="","",LOOKUP(_xlfn.CONCAT(P23,", ",Q23),'[1]T+S Costs'!$F$2:$F$3138,'[1]T+S Costs'!$N$2:$N$3138)) -> 20.384279 | Y23: =IF(X23="","",((X23*$B$60/$B$59)*$C$44)/$C$28) -> 0.40954956 | Z23: =IF(Y23="","",W23+Y23) -> 7.057662
A24: First Year Fixed O&M Cost, $ | B24: ='[1]Net-Zero O&M'!$G$19 -> 26801463 | P24: =IF('[1]All Data '!AZ29="","",'[1]All Data '!AZ29) -> Clinton County | Q24: =IF('[1]All Data '!BB29="","",'[1]All Data '!BB29) -> IN | R24: =IF('[1]All Data '!BD29="","",'[1]All Data '!BD29) -> 70 | S24: =IF(R24="","",'[1]All Data '!BE29) -> 0.2 | T24: =IF(S24="","",[1]Inputs_Outputs!$B$8*(1-'LOCH Calc COE Calc'!S24)) -> 254466.23 | U24: =IF(S24="","",R24*T24*365*$B$19/100) -> 52012898 | V24: =IF(S24="","",(U24*$B$19)/(($B$28)*$B$19)) -> 1.7943111 | W24: =IF(S24="","",V24+$C$49+$C$50+$C$51) -> 6.6227146 | X24: =IF(W24="","",LOOKUP(_xlfn.CONCAT(P24,", ",Q24),'[1]T+S Costs'!$F$2:$F$3138,'[1]T+S Costs'!$N$2:$N$3138)) -> 13.759103 | Y24: =IF(X24="","",((X24*$B$60/$B$59)*$C$44)/$C$28) -> 0.27644022 | Z24: =IF(Y24="","",W24+Y24) -> 6.8991548
A25: First Year Variable O&M Cost, $ (100% CF) | B25: ='[1]Net-Zero O&M'!$G$51/B19 -> 23037271 | P25: =IF('[1]All Data '!AZ30="","",'[1]All Data '!AZ30) -> Boone County | Q25: =IF('[1]All Data '!BB30="","",'[1]All Data '!BB30) -> IL | R25: =IF('[1]All Data '!BD30="","",'[1]All Data '!BD30) -> 70 | S25: =IF(R25="","",'[1]All Data '!BE30) -> 0.2 | T25: =IF(S25="","",[1]Inputs_Outputs!$B$8*(1-'LOCH Calc COE Calc'!S25)) -> 254466.23 | U25: =IF(S25="","",R25*T25*365*$B$19/100) -> 52012898 | V25: =IF(S25="","",(U25*$B$19)/(($B$28)*$B$19)) -> 1.7943111 | W25: =IF(S25="","",V25+$C$49+$C$50+$C$51) -> 6.6227146 | X25: =IF(W25="","",LOOKUP(_xlfn.CONCAT(P25,", ",Q25),'[1]T+S Costs'!$F$2:$F$3138,'[1]T+S Costs'!$N$2:$N$3138)) -> 20.927722 | Y25: =IF(X25="","",((X25*$B$60/$B$59)*$C$44)/$C$28) -> 0.4204681 | Z25: =IF(Y25="","",W25+Y25) -> 7.0431827
A26: Gross Plant Output, kW | B26: ='[1]Net-Zero Cap'!$H$222 -> 11900 | P26: =IF('[1]All Data '!AZ31="","",'[1]All Data '!AZ31) -> Clay County | Q26: =IF('[1]All Data '!BB31="","",'[1]All Data '!BB31) -> SD | R26: =IF('[1]All Data '!BD31="","",'[1]All Data '!BD31) -> 70 | S26: =IF(R26="","",'[1]All Data '!BE31) -> 0.2 | T26: =IF(S26="","",[1]Inputs_Outputs!$B$8*(1-'LOCH Calc COE Calc'!S26)) -> 254466.23 | U26: =IF(S26="","",R26*T26*365*$B$19/100) -> 52012898 | V26: =IF(S26="","",(U26*$B$19)/(($B$28)*$B$19)) -> 1.7943111 | W26: =IF(S26="","",V26+$C$49+$C$50+$C$51) -> 6.6227146 | X26: =IF(W26="","",LOOKUP(_xlfn.CONCAT(P26,", ",Q26),'[1]T+S Costs'!$F$2:$F$3138,'[1]T+S Costs'!$N$2:$N$3138)) -> 24.883277 | Y26: =IF(X26="","",((X26*$B$60/$B$59)*$C$44)/$C$28) -> 0.49994091 | Z26: =IF(Y26="","",W26+Y26) -> 7.1226555
A27: H2 Production Rate, kg H2/day | B27: ='[1]Net-Zero Cap'!$D$4 -> 79418.272 | P27: =IF('[1]All Data '!AZ32="","",'[1]All Data '!AZ32) -> Union County | Q27: =IF('[1]All Data '!BB32="","",'[1]All Data '!BB32) -> SD | R27: =IF('[1]All Data '!BD32="","",'[1]All Data '!BD32) -> 70 | S27: =IF(R27="","",'[1]All Data '!BE32) -> 0.2 | T27: =IF(S27="","",[1]Inputs_Outputs!$B$8*(1-'LOCH Calc COE Calc'!S27)) -> 254466.23 | U27: =IF(S27="","",R27*T27*365*$B$19/100) -> 52012898 | V27: =IF(S27="","",(U27*$B$19)/(($B$28)*$B$19)) -> 1.7943111 | W27: =IF(S27="","",V27+$C$49+$C$50+$C$51) -> 6.6227146 | X27: =IF(W27="","",LOOKUP(_xlfn.CONCAT(P27,", ",Q27),'[1]T+S Costs'!$F$2:$F$3138,'[1]T+S Costs'!$N$2:$N$3138)) -> 25.118667 | Y27: =IF(X27="","",((X27*$B$60/$B$59)*$C$44)/$C$28) -> 0.50467023 | Z27: =IF(Y27="","",W27+Y27) -> 7.1273848
A28: Annual H2 Production, kg H2 (100%) | B28: =B27*365 -> 28987669 | C28: =B28*B19 -> 23190135 | P28: =IF('[1]All Data '!AZ33="","",'[1]All Data '!AZ33) -> Bureau County | Q28: =IF('[1]All Data '!BB33="","",'[1]All Data '!BB33) -> IL | R28: =IF('[1]All Data '!BD33="","",'[1]All Data '!BD33) -> 70 | S28: =IF(R28="","",'[1]All Data '!BE33) -> 0.2 | T28: =IF(S28="","",[1]Inputs_Outputs!$B$8*(1-'LOCH Calc COE Calc'!S28)) -> 254466.23 | U28: =IF(S28="","",R28*T28*365*$B$19/100) -> 52012898 | V28: =IF(S28="","",(U28*$B$19)/(($B$28)*$B$19)) -> 1.7943111 | W28: =IF(S28="","",V28+$C$49+$C$50+$C$51) -> 6.6227146 | X28: =IF(W28="","",LOOKUP(_xlfn.CONCAT(P28,", ",Q28),'[1]T+S Costs'!$F$2:$F$3138,'[1]T+S Costs'!$N$2:$N$3138)) -> 11.996769 | Y28: =IF(X28="","",((X28*$B$60/$B$59)*$C$44)/$C$28) -> 0.24103238 | Z28: =IF(Y28="","",W28+Y28) -> 6.863747
A29: Rev4 Method for Rev4 LCOH; LCOH, $/kg H2 [No T&S] | B29: =(($B$4*((B20*1000)*$C$4))+B24+((B25+B23)*B19))/(B28*B19) -> 6.0835339 | P29: =IF('[1]All Data '!AZ34="","",'[1]All Data '!AZ34) -> Iroquois County | Q29: =IF('[1]All Data '!BB34="","",'[1]All Data '!BB34) -> IL | R29: =IF('[1]All Data '!BD34="","",'[1]All Data '!BD34) -> 70 | S29: =IF(R29="","",'[1]All Data '!BE34) -> 0.2 | T29: =IF(S29="","",[1]Inputs_Outputs!$B$8*(1-'LOCH Calc COE Calc'!S29)) -> 254466.23 | U29: =IF(S29="","",R29*T29*365*$B$19/100) -> 52012898 | V29: =IF(S29="","",(U29*$B$19)/(($B$28)*$B$19)) -> 1.7943111 | W29: =IF(S29="","",V29+$C$49+$C$50+$C$51) -> 6.6227146 | X29: =IF(W29="","",LOOKUP(_xlfn.CONCAT(P29,", ",Q29),'[1]T+S Costs'!$F$2:$F$3138,'[1]T+S Costs'!$N$2:$N$3138)) -> 11.733686 | Y29: =IF(X29="","",((X29*$B$60/$B$59)*$C$44)/$C$28) -> 0.23574667 | Z29: =IF(Y29="","",W29+Y29) -> 6.8584613
A30: BEC, $/[kg H2/day] | B30: =('[1]Net-Zero Cap'!$H$154*1000)/B27 -> 5576.3664 | P30: =IF('[1]All Data '!AZ35="","",'[1]All Data '!AZ35) -> Hill County | Q30: =IF('[1]All Data '!BB35="","",'[1]All Data '!BB35) -> MT | R30: =IF('[1]All Data '!BD35="","",'[1]All Data '!BD35) -> 70 | S30: =IF(R30="","",'[1]All Data '!BE35) -> 0.16 | T30: =IF(S30="","",[1]Inputs_Outputs!$B$8*(1-'LOCH Calc COE Calc'!S30)) -> 267189.54 | U30: =IF(S30="","",R30*T30*365*$B$19/100) -> 54613542 | V30: =IF(S30="","",(U30*$B$19)/(($B$28)*$B$19)) -> 1.8840267 | W30: =IF(S30="","",V30+$C$49+$C$50+$C$51) -> 6.7124302 | X30: =IF(W30="","",LOOKUP(_xlfn.CONCAT(P30,", ",Q30),'[1]T+S Costs'!$F$2:$F$3138,'[1]T+S Costs'!$N$2:$N$3138)) -> 19.663871 | Y30: =IF(X30="","",((X30*$B$60/$B$59)*$C$44)/$C$28) -> 0.39507551 | Z30: =IF(Y30="","",W30+Y30) -> 7.1075057
A31: TPC, $/[kg H2/day] | B31: ='[1]Net-Zero Cap'!$M$154 -> 7896.2639 | P31: =IF('[1]All Data '!AZ36="","",'[1]All Data '!AZ36) -> Redwood County | Q31: =IF('[1]All Data '!BB36="","",'[1]All Data '!BB36) -> MN | R31: =IF('[1]All Data '!BD36="","",'[1]All Data '!BD36) -> 70 | S31: =IF(R31="","",'[1]All Data '!BE36) -> 0.19994057 | T31: =IF(S31="","",[1]Inputs_Outputs!$B$8*(1-'LOCH Calc COE Calc'!S31)) -> 254485.14 | U31: =IF(S31="","",R31*T31*365*$B$19/100) -> 52016762 | V31: =IF(S31="","",(U31*$B$19)/(($B$28)*$B$19)) -> 1.7944444 | W31: =IF(S31="","",V31+$C$49+$C$50+$C$51) -> 6.6228479 | X31: =IF(W31="","",LOOKUP(_xlfn.CONCAT(P31,", ",Q31),'[1]T+S Costs'!$F$2:$F$3138,'[1]T+S Costs'!$N$2:$N$3138)) -> 25.119761 | Y31: =IF(X31="","",((X31*$B$60/$B$59)*$C$44)/$C$28) -> 0.50469222 | Z31: =IF(Y31="","",W31+Y31) -> 7.1275401
A32: TOC, $/[kg H2/day] | B32: ='[1]Net-Zero Cap'!$U$22 -> 9787.7927 | P32: =IF('[1]All Data '!AZ37="","",'[1]All Data '!AZ37) -> Cass County | Q32: =IF('[1]All Data '!BB37="","",'[1]All Data '!BB37) -> NE | R32: =IF('[1]All Data '!BD37="","",'[1]All Data '!BD37) -> 70 | S32: =IF(R32="","",'[1]All Data '!BE37) -> 0.2 | T32: =IF(S32="","",[1]Inputs_Outputs!$B$8*(1-'LOCH Calc COE Calc'!S32)) -> 254466.23 | U32: =IF(S32="","",R32*T32*365*$B$19/100) -> 52012898 | V32: =IF(S32="","",(U32*$B$19)/(($B$28)*$B$19)) -> 1.7943111 | W32: =IF(S32="","",V32+$C$49+$C$50+$C$51) -> 6.6227146 | X32: =IF(W32="","",LOOKUP(_xlfn.CONCAT(P32,", ",Q32),'[1]T+S Costs'!$F$2:$F$3138,'[1]T+S Costs'!$N$2:$N$3138)) -> 17.199598 | Y32: =IF(X32="","",((X32*$B$60/$B$59)*$C$44)/$C$28) -> 0.34556473 | Z32: =IF(Y32="","",W32+Y32) -> 6.9682793
A33: TASC, $/[kg H2/day] | B33: ='[1]Net-Zero Cap'!$U$24 -> 10926.47 | P33: =IF('[1]All Data '!AZ38="","",'[1]All Data '!AZ38) -> Henderson County | Q33: =IF('[1]All Data '!BB38="","",'[1]All Data '!BB38) -> IL | R33: =IF('[1]All Data '!BD38="","",'[1]All Data '!BD38) -> 70 | S33: =IF(R33="","",'[1]All Data '!BE38) -> 0.2 | T33: =IF(S33="","",[1]Inputs_Outputs!$B$8*(1-'LOCH Calc COE Calc'!S33)) -> 254466.23 | U33: =IF(S33="","",R33*T33*365*$B$19/100) -> 52012898 | V33: =IF(S33="","",(U33*$B$19)/(($B$28)*$B$19)) -> 1.7943111 | W33: =IF(S33="","",V33+$C$49+$C$50+$C$51) -> 6.6227146 | X33: =IF(W33="","",LOOKUP(_xlfn.CONCAT(P33,", ",Q33),'[1]T+S Costs'!$F$2:$F$3138,'[1]T+S Costs'!$N$2:$N$3138)) -> 11.996769 | Y33: =IF(X33="","",((X33*$B$60/$B$59)*$C$44)/$C$28) -> 0.24103238 | Z33: =IF(Y33="","",W33+Y33) -> 6.863747
A34: Eng'g CM, H.O. & Fee, $/[kg H2/day] | B34: ='[1]Net-Zero Cap'!$I$154*1000/B27 -> 807.72287 | P34: =IF('[1]All Data '!AZ39="","",'[1]All Data '!AZ39) -> Otoe County | Q34: =IF('[1]All Data '!BB39="","",'[1]All Data '!BB39) -> NE | R34: =IF('[1]All Data '!BD39="","",'[1]All Data '!BD39) -> 70 | S34: =IF(R34="","",'[1]All Data '!BE39) -> 0.2 | T34: =IF(S34="","",[1]Inputs_Outputs!$B$8*(1-'LOCH Calc COE Calc'!S34)) -> 254466.23 | U34: =IF(S34="","",R34*T34*365*$B$19/100) -> 52012898 | V34: =IF(S34="","",(U34*$B$19)/(($B$28)*$B$19)) -> 1.7943111 | W34: =IF(S34="","",V34+$C$49+$C$50+$C$51) -> 6.6227146 | X34: =IF(W34="","",LOOKUP(_xlfn.CONCAT(P34,", ",Q34),'[1]T+S Costs'!$F$2:$F$3138,'[1]T+S Costs'!$N$2:$N$3138)) -> 20.874117 | Y34: =IF(X34="","",((X34*$B$60/$B$59)*$C$44)/$C$28) -> 0.41939111 | Z34: =IF(Y34="","",W34+Y34) -> 7.0421057
A35: Eng'g CM, H.O. & Fee, % of TOC | B35: =B34/B32*100 -> 8.2523496 | P35: =IF('[1]All Data '!AZ40="","",'[1]All Data '!AZ40) -> Marshall County | Q35: =IF('[1]All Data '!BB40="","",'[1]All Data '!BB40) -> IL | R35: =IF('[1]All Data '!BD40="","",'[1]All Data '!BD40) -> 70 | S35: =IF(R35="","",'[1]All Data '!BE40) -> 0.2 | T35: =IF(S35="","",[1]Inputs_Outputs!$B$8*(1-'LOCH Calc COE Calc'!S35)) -> 254466.23 | U35: =IF(S35="","",R35*T35*365*$B$19/100) -> 52012898 | V35: =IF(S35="","",(U35*$B$19)/(($B$28)*$B$19)) -> 1.7943111 | W35: =IF(S35="","",V35+$C$49+$C$50+$C$51) -> 6.6227146 | X35: =IF(W35="","",LOOKUP(_xlfn.CONCAT(P35,", ",Q35),'[1]T+S Costs'!$F$2:$F$3138,'[1]T+S Costs'!$N$2:$N$3138)) -> 19.681542 | Y35: =IF(X35="","",((X35*$B$60/$B$59)*$C$44)/$C$28) -> 0.39543055 | Z35: =IF(Y35="","",W35+Y35) -> 7.0181452
A36: Process Contingency, $/[kg H2/day] | B36: ='[1]Net-Zero Cap'!$J$154*1000/B27 -> 353.61549 | P36: =IF('[1]All Data '!AZ41="","",'[1]All Data '!AZ41) -> Platte County | Q36: =IF('[1]All Data '!BB41="","",'[1]All Data '!BB41) -> NE | R36: =IF('[1]All Data '!BD41="","",'[1]All Data '!BD41) -> 70 | S36: =IF(R36="","",'[1]All Data '!BE41) -> 0.2 | T36: =IF(S36="","",[1]Inputs_Outputs!$B$8*(1-'LOCH Calc COE Calc'!S36)) -> 254466.23 | U36: =IF(S36="","",R36*T36*365*$B$19/100) -> 52012898 | V36: =IF(S36="","",(U36*$B$19)/(($B$28)*$B$19)) -> 1.7943111 | W36: =IF(S36="","",V36+$C$49+$C$50+$C$51) -> 6.6227146 | X36: =IF(W36="","",LOOKUP(_xlfn.CONCAT(P36,", ",Q36),'[1]T+S Costs'!$F$2:$F$3138,'[1]T+S Costs'!$N$2:$N$3138)) -> 21.621825 | Y36: =IF(X36="","",((X36*$B$60/$B$59)*$C$44)/$C$28) -> 0.43441364 | Z36: =IF(Y36="","",W36+Y36) -> 7.0571282
A37: Process Contingency, % of TOC | B37: =B36/B32*100 -> 3.6128216 | P37: =IF('[1]All Data '!AZ42="","",'[1]All Data '!AZ42) -> La Salle County | Q37: =IF('[1]All Data '!BB42="","",'[1]All Data '!BB42) -> IL | R37: =IF('[1]All Data '!BD42="","",'[1]All Data '!BD42) -> 70 | S37: =IF(R37="","",'[1]All Data '!BE42) -> 0.2 | T37: =IF(S37="","",[1]Inputs_Outputs!$B$8*(1-'LOCH Calc COE Calc'!S37)) -> 254466.23 | U37: =IF(S37="","",R37*T37*365*$B$19/100) -> 52012898 | V37: =IF(S37="","",(U37*$B$19)/(($B$28)*$B$19)) -> 1.7943111 | W37: =IF(S37="","",V37+$C$49+$C$50+$C$51) -> 6.6227146 | X37: =IF(W37="","",LOOKUP(_xlfn.CONCAT(P37,", ",Q37),'[1]T+S Costs'!$F$2:$F$3138,'[1]T+S Costs'!$N$2:$N$3138)) -> 11.996769 | Y37: =IF(X37="","",((X37*$B$60/$B$59)*$C$44)/$C$28) -> 0.24103238 | Z37: =IF(Y37="","",W37+Y37) -> 6.863747
A38: Project Contingency, $/[kg H2/day] | B38: ='[1]Net-Zero Cap'!$K$154*1000/B27 -> 1158.5591 | P38: =IF('[1]All Data '!AZ43="","",'[1]All Data '!AZ43) -> Custer County | Q38: =IF('[1]All Data '!BB43="","",'[1]All Data '!BB43) -> NE | R38: =IF('[1]All Data '!BD43="","",'[1]All Data '!BD43) -> 70 | S38: =IF(R38="","",'[1]All Data '!BE43) -> 0.2 | T38: =IF(S38="","",[1]Inputs_Outputs!$B$8*(1-'LOCH Calc COE Calc'!S38)) -> 254466.23 | U38: =IF(S38="","",R38*T38*365*$B$19/100) -> 52012898 | V38: =IF(S38="","",(U38*$B$19)/(($B$28)*$B$19)) -> 1.7943111 | W38: =IF(S38="","",V38+$C$49+$C$50+$C$51) -> 6.6227146 | X38: =IF(W38="","",LOOKUP(_xlfn.CONCAT(P38,", ",Q38),'[1]T+S Costs'!$F$2:$F$3138,'[1]T+S Costs'!$N$2:$N$3138)) -> 16.907729 | Y38: =IF(X38="","",((X38*$B$60/$B$59)*$C$44)/$C$28) -> 0.33970064 | Z38: =IF(Y38="","",W38+Y38) -> 6.9624152
A39: Project Contingency, % of TOC | B39: =B38/B32*100 -> 11.836777 | P39: =IF('[1]All Data '!AZ44="","",'[1]All Data '!AZ44) -> Boone County | Q39: =IF('[1]All Data '!BB44="","",'[1]All Data '!BB44) -> IN | R39: =IF('[1]All Data '!BD44="","",'[1]All Data '!BD44) -> 70 | S39: =IF(R39="","",'[1]All Data '!BE44) -> 0.2 | T39: =IF(S39="","",[1]Inputs_Outputs!$B$8*(1-'LOCH Calc COE Calc'!S39)) -> 254466.23 | U39: =IF(S39="","",R39*T39*365*$B$19/100) -> 52012898 | V39: =IF(S39="","",(U39*$B$19)/(($B$28)*$B$19)) -> 1.7943111 | W39: =IF(S39="","",V39+$C$49+$C$50+$C$51) -> 6.6227146 | X39: =IF(W39="","",LOOKUP(_xlfn.CONCAT(P39,", ",Q39),'[1]T+S Costs'!$F$2:$F$3138,'[1]T+S Costs'!$N$2:$N$3138)) -> 20.927722 | Y39: =IF(X39="","",((X39*$B$60/$B$59)*$C$44)/$C$28) -> 0.4204681 | Z39: =IF(Y39="","",W39+Y39) -> 7.0431827
A40: Owner's Costs, $/[kg H2/day] | B40: =B32-B31 -> 1891.5288 | P40: =IF('[1]All Data '!AZ45="","",'[1]All Data '!AZ45) -> Nicollet County | Q40: =IF('[1]All Data '!BB45="","",'[1]All Data '!BB45) -> MN | R40: =IF('[1]All Data '!BD45="","",'[1]All Data '!BD45) -> 70 | S40: =IF(R40="","",'[1]All Data '!BE45) -> 0.199876 | T40: =IF(S40="","",[1]Inputs_Outputs!$B$8*(1-'LOCH Calc COE Calc'!S40)) -> 254505.67 | U40: =IF(S40="","",R40*T40*365*$B$19/100) -> 52020960 | V40: =IF(S40="","",(U40*$B$19)/(($B$28)*$B$19)) -> 1.7945893 | W40: =IF(S40="","",V40+$C$49+$C$50+$C$51) -> 6.6229927 | X40: =IF(W40="","",LOOKUP(_xlfn.CONCAT(P40,", ",Q40),'[1]T+S Costs'!$F$2:$F$3138,'[1]T+S Costs'!$N$2:$N$3138)) -> 28.238641 | Y40: =IF(X40="","",((X40*$B$60/$B$59)*$C$44)/$C$28) -> 0.56735501 | Z40: =IF(Y40="","",W40+Y40) -> 7.1903477
...
